2025-07-18 23:10:33 - App - INFO - Shutting down
2025-07-18 23:10:33 - App - INFO - Waiting for application shutdown.
2025-07-18 23:10:33 - App - INFO - Application shutdown complete.
2025-07-18 23:10:33 - App - INFO - Finished server process [15992]
18-07-2025 23:10:44 - middleware_logger - INFO - Line: 28 - Starting api...
18-07-2025 23:10:44 - middleware_logger - INFO - Line: 40 - Api started
2025-07-18 23:10:44 - App - INFO - Started server process [16700]
2025-07-18 23:10:44 - App - INFO - Waiting for application startup.
2025-07-18 23:10:44 - App - INFO - Application startup complete.
2025-07-18 23:10:44 - App - INFO - Uvicorn running on http://127.0.0.1:5000 (Press CTRL+C to quit)
2025-07-18 23:12:40 - App - INFO - 127.0.0.1:61614 - "GET /docs HTTP/1.1" 200
2025-07-18 23:12:40 - App - INFO - 127.0.0.1:61614 - "GET /openapi.json HTTP/1.1" 200
2025-07-18 23:13:14 - App - INFO - 127.0.0.1:61752 - "POST /get_ner_prediction HTTP/1.1" 200
2025-07-18 23:22:03 - App - INFO - Shutting down
2025-07-18 23:22:03 - App - INFO - Finished server process [16700]
2025-07-18 23:22:03 - App - ERROR - Traceback (most recent call last):
  File "C:\Program Files\Python311\Lib\asyncio\runners.py", line 190, in run
    return runner.run(main)
           ^^^^^^^^^^^^^^^^
  File "C:\Program Files\Python311\Lib\asyncio\runners.py", line 118, in run
    return self._loop.run_until_complete(task)
           ^^^^^^^^^^^^^^^^^^^^^^^^^^^^^^^^^^^
  File "C:\Program Files\Python311\Lib\asyncio\base_events.py", line 640, in run_until_complete
    self.run_forever()
  File "C:\Program Files\Python311\Lib\asyncio\windows_events.py", line 321, in run_forever
    super().run_forever()
  File "C:\Program Files\Python311\Lib\asyncio\base_events.py", line 607, in run_forever
    self._run_once()
  File "C:\Program Files\Python311\Lib\asyncio\base_events.py", line 1922, in _run_once
    handle._run()
  File "C:\Program Files\Python311\Lib\asyncio\events.py", line 80, in _run
    self._context.run(self._callback, *self._args)
  File "C:\Users\table\PycharmProjects\MojeCos\venv11\Lib\site-packages\uvicorn\server.py", line 68, in serve
    with self.capture_signals():
  File "C:\Program Files\Python311\Lib\contextlib.py", line 144, in __exit__
    next(self.gen)
  File "C:\Users\table\PycharmProjects\MojeCos\venv11\Lib\site-packages\uvicorn\server.py", line 332, in capture_signals
    signal.raise_signal(captured_signal)
  File "C:\Program Files\Python311\Lib\asyncio\runners.py", line 157, in _on_sigint
    raise KeyboardInterrupt()
KeyboardInterrupt

During handling of the above exception, another exception occurred:

Traceback (most recent call last):
  File "C:\Users\table\PycharmProjects\MojeCos\venv11\Lib\site-packages\starlette\routing.py", line 700, in lifespan
    await receive()
  File "C:\Users\table\PycharmProjects\MojeCos\venv11\Lib\site-packages\uvicorn\lifespan\on.py", line 137, in receive
    return await self.receive_queue.get()
           ^^^^^^^^^^^^^^^^^^^^^^^^^^^^^^
  File "C:\Program Files\Python311\Lib\asyncio\queues.py", line 158, in get
    await getter
asyncio.exceptions.CancelledError

18-07-2025 23:22:13 - middleware_logger - INFO - Line: 28 - Starting api...
18-07-2025 23:22:13 - middleware_logger - INFO - Line: 40 - Api started
2025-07-18 23:22:13 - App - INFO - Started server process [7192]
2025-07-18 23:22:13 - App - INFO - Waiting for application startup.
2025-07-18 23:22:13 - App - INFO - Application startup complete.
2025-07-18 23:22:13 - App - INFO - Uvicorn running on http://127.0.0.1:5000 (Press CTRL+C to quit)
2025-07-18 23:22:13 - App - INFO - 127.0.0.1:61940 - "GET /docs HTTP/1.1" 200
2025-07-18 23:22:13 - App - INFO - 127.0.0.1:61940 - "GET /openapi.json HTTP/1.1" 200
2025-07-18 23:28:39 - App - INFO - Shutting down
2025-07-18 23:28:39 - App - INFO - Finished server process [7192]
2025-07-18 23:28:39 - App - ERROR - Traceback (most recent call last):
  File "C:\Program Files\Python311\Lib\asyncio\runners.py", line 190, in run
    return runner.run(main)
           ^^^^^^^^^^^^^^^^
  File "C:\Program Files\Python311\Lib\asyncio\runners.py", line 118, in run
    return self._loop.run_until_complete(task)
           ^^^^^^^^^^^^^^^^^^^^^^^^^^^^^^^^^^^
  File "C:\Program Files\Python311\Lib\asyncio\base_events.py", line 640, in run_until_complete
    self.run_forever()
  File "C:\Program Files\Python311\Lib\asyncio\windows_events.py", line 321, in run_forever
    super().run_forever()
  File "C:\Program Files\Python311\Lib\asyncio\base_events.py", line 607, in run_forever
    self._run_once()
  File "C:\Program Files\Python311\Lib\asyncio\base_events.py", line 1922, in _run_once
    handle._run()
  File "C:\Program Files\Python311\Lib\asyncio\events.py", line 80, in _run
    self._context.run(self._callback, *self._args)
  File "C:\Users\table\PycharmProjects\MojeCos\venv11\Lib\site-packages\uvicorn\server.py", line 68, in serve
    with self.capture_signals():
  File "C:\Program Files\Python311\Lib\contextlib.py", line 144, in __exit__
    next(self.gen)
  File "C:\Users\table\PycharmProjects\MojeCos\venv11\Lib\site-packages\uvicorn\server.py", line 332, in capture_signals
    signal.raise_signal(captured_signal)
  File "C:\Program Files\Python311\Lib\asyncio\runners.py", line 157, in _on_sigint
    raise KeyboardInterrupt()
KeyboardInterrupt

During handling of the above exception, another exception occurred:

Traceback (most recent call last):
  File "C:\Users\table\PycharmProjects\MojeCos\venv11\Lib\site-packages\starlette\routing.py", line 700, in lifespan
    await receive()
  File "C:\Users\table\PycharmProjects\MojeCos\venv11\Lib\site-packages\uvicorn\lifespan\on.py", line 137, in receive
    return await self.receive_queue.get()
           ^^^^^^^^^^^^^^^^^^^^^^^^^^^^^^
  File "C:\Program Files\Python311\Lib\asyncio\queues.py", line 158, in get
    await getter
asyncio.exceptions.CancelledError

18-07-2025 23:28:49 - middleware_logger - INFO - Line: 28 - Starting api...
18-07-2025 23:28:49 - middleware_logger - INFO - Line: 40 - Api started
2025-07-18 23:28:49 - App - INFO - Started server process [12732]
2025-07-18 23:28:49 - App - INFO - Waiting for application startup.
2025-07-18 23:28:49 - App - INFO - Application startup complete.
2025-07-18 23:28:49 - App - INFO - Uvicorn running on http://127.0.0.1:5000 (Press CTRL+C to quit)
2025-07-18 23:28:56 - App - INFO - 127.0.0.1:62065 - "GET /docs HTTP/1.1" 200
2025-07-18 23:28:56 - App - INFO - 127.0.0.1:62065 - "GET /openapi.json HTTP/1.1" 200
2025-07-18 23:29:09 - App - INFO - 127.0.0.1:62072 - "POST /get_ner_prediction HTTP/1.1" 200
2025-07-18 23:30:16 - App - INFO - Shutting down
2025-07-18 23:30:16 - App - INFO - Waiting for application shutdown.
2025-07-18 23:30:16 - App - INFO - Application shutdown complete.
2025-07-18 23:30:16 - App - INFO - Finished server process [12732]
18-07-2025 23:32:49 - middleware_logger - INFO - Line: 28 - Starting api...
18-07-2025 23:32:49 - middleware_logger - INFO - Line: 40 - Api started
2025-07-18 23:32:50 - App - INFO - Started server process [20260]
2025-07-18 23:32:50 - App - INFO - Waiting for application startup.
2025-07-18 23:32:50 - App - INFO - Application startup complete.
2025-07-18 23:32:50 - App - INFO - Uvicorn running on http://127.0.0.1:5000 (Press CTRL+C to quit)
2025-07-18 23:32:50 - App - INFO - 127.0.0.1:62152 - "GET /docs HTTP/1.1" 200
2025-07-18 23:32:50 - App - INFO - 127.0.0.1:62152 - "GET /openapi.json HTTP/1.1" 200
2025-07-18 23:32:58 - App - INFO - 127.0.0.1:62151 - "POST /get_ner_prediction HTTP/1.1" 200
2025-07-18 23:33:24 - App - INFO - Shutting down
2025-07-18 23:33:24 - App - INFO - Finished server process [20260]
2025-07-18 23:33:24 - App - ERROR - Traceback (most recent call last):
  File "C:\Program Files\Python311\Lib\asyncio\runners.py", line 190, in run
    return runner.run(main)
           ^^^^^^^^^^^^^^^^
  File "C:\Program Files\Python311\Lib\asyncio\runners.py", line 118, in run
    return self._loop.run_until_complete(task)
           ^^^^^^^^^^^^^^^^^^^^^^^^^^^^^^^^^^^
  File "C:\Program Files\Python311\Lib\asyncio\base_events.py", line 640, in run_until_complete
    self.run_forever()
  File "C:\Program Files\Python311\Lib\asyncio\windows_events.py", line 321, in run_forever
    super().run_forever()
  File "C:\Program Files\Python311\Lib\asyncio\base_events.py", line 607, in run_forever
    self._run_once()
  File "C:\Program Files\Python311\Lib\asyncio\base_events.py", line 1922, in _run_once
    handle._run()
  File "C:\Program Files\Python311\Lib\asyncio\events.py", line 80, in _run
    self._context.run(self._callback, *self._args)
  File "C:\Users\table\PycharmProjects\MojeCos\venv11\Lib\site-packages\uvicorn\server.py", line 68, in serve
    with self.capture_signals():
  File "C:\Program Files\Python311\Lib\contextlib.py", line 144, in __exit__
    next(self.gen)
  File "C:\Users\table\PycharmProjects\MojeCos\venv11\Lib\site-packages\uvicorn\server.py", line 332, in capture_signals
    signal.raise_signal(captured_signal)
  File "C:\Program Files\Python311\Lib\asyncio\runners.py", line 157, in _on_sigint
    raise KeyboardInterrupt()
KeyboardInterrupt

During handling of the above exception, another exception occurred:

Traceback (most recent call last):
  File "C:\Users\table\PycharmProjects\MojeCos\venv11\Lib\site-packages\starlette\routing.py", line 700, in lifespan
    await receive()
  File "C:\Users\table\PycharmProjects\MojeCos\venv11\Lib\site-packages\uvicorn\lifespan\on.py", line 137, in receive
    return await self.receive_queue.get()
           ^^^^^^^^^^^^^^^^^^^^^^^^^^^^^^
  File "C:\Program Files\Python311\Lib\asyncio\queues.py", line 158, in get
    await getter
asyncio.exceptions.CancelledError

19-07-2025 19:32:36 - middleware_logger - INFO - Line: 28 - Starting api...
19-07-2025 19:32:36 - middleware_logger - INFO - Line: 39 - Api started
2025-07-19 19:32:36 - App - INFO - Started server process [13100]
2025-07-19 19:32:36 - App - INFO - Waiting for application startup.
2025-07-19 19:32:36 - App - INFO - Application startup complete.
2025-07-19 19:32:36 - App - INFO - Uvicorn running on http://127.0.0.1:5000 (Press CTRL+C to quit)
2025-07-19 19:32:42 - App - INFO - 127.0.0.1:56004 - "GET / HTTP/1.1" 200
2025-07-19 19:32:42 - App - INFO - 127.0.0.1:56004 - "GET /favicon.ico HTTP/1.1" 404
2025-07-19 19:32:45 - App - INFO - 127.0.0.1:56004 - "GET /docs HTTP/1.1" 200
2025-07-19 19:32:45 - App - INFO - 127.0.0.1:56004 - "GET /openapi.json HTTP/1.1" 200
2025-07-19 19:34:02 - App - INFO - 127.0.0.1:56017 - "POST /get_ner_prediction HTTP/1.1" 200
2025-07-19 19:37:32 - App - INFO - Shutting down
2025-07-19 19:37:32 - App - INFO - Finished server process [13100]
2025-07-19 19:37:32 - App - ERROR - Traceback (most recent call last):
  File "C:\Program Files\Python311\Lib\asyncio\runners.py", line 190, in run
    return runner.run(main)
           ^^^^^^^^^^^^^^^^
  File "C:\Program Files\Python311\Lib\asyncio\runners.py", line 118, in run
    return self._loop.run_until_complete(task)
           ^^^^^^^^^^^^^^^^^^^^^^^^^^^^^^^^^^^
  File "C:\Program Files\Python311\Lib\asyncio\base_events.py", line 640, in run_until_complete
    self.run_forever()
  File "C:\Program Files\Python311\Lib\asyncio\windows_events.py", line 321, in run_forever
    super().run_forever()
  File "C:\Program Files\Python311\Lib\asyncio\base_events.py", line 607, in run_forever
    self._run_once()
  File "C:\Program Files\Python311\Lib\asyncio\base_events.py", line 1922, in _run_once
    handle._run()
  File "C:\Program Files\Python311\Lib\asyncio\events.py", line 80, in _run
    self._context.run(self._callback, *self._args)
  File "C:\Users\table\PycharmProjects\MojeCos\venv11\Lib\site-packages\uvicorn\server.py", line 68, in serve
    with self.capture_signals():
  File "C:\Program Files\Python311\Lib\contextlib.py", line 144, in __exit__
    next(self.gen)
  File "C:\Users\table\PycharmProjects\MojeCos\venv11\Lib\site-packages\uvicorn\server.py", line 332, in capture_signals
    signal.raise_signal(captured_signal)
  File "C:\Program Files\Python311\Lib\asyncio\runners.py", line 157, in _on_sigint
    raise KeyboardInterrupt()
KeyboardInterrupt

During handling of the above exception, another exception occurred:

Traceback (most recent call last):
  File "C:\Users\table\PycharmProjects\MojeCos\venv11\Lib\site-packages\starlette\routing.py", line 700, in lifespan
    await receive()
  File "C:\Users\table\PycharmProjects\MojeCos\venv11\Lib\site-packages\uvicorn\lifespan\on.py", line 137, in receive
    return await self.receive_queue.get()
           ^^^^^^^^^^^^^^^^^^^^^^^^^^^^^^
  File "C:\Program Files\Python311\Lib\asyncio\queues.py", line 158, in get
    await getter
asyncio.exceptions.CancelledError

20-07-2025 13:33:30 - middleware_logger - INFO - Line: 28 - Starting api...
20-07-2025 13:33:31 - middleware_logger - INFO - Line: 39 - Api started
2025-07-20 13:33:31 - App - INFO - Started server process [16496]
2025-07-20 13:33:31 - App - INFO - Waiting for application startup.
2025-07-20 13:33:31 - App - INFO - Application startup complete.
2025-07-20 13:33:31 - App - INFO - Uvicorn running on http://127.0.0.1:5000 (Press CTRL+C to quit)
2025-07-20 13:33:34 - App - INFO - 127.0.0.1:65368 - "GET / HTTP/1.1" 200
2025-07-20 13:33:34 - App - INFO - 127.0.0.1:65368 - "GET /favicon.ico HTTP/1.1" 404
2025-07-20 13:33:36 - App - INFO - 127.0.0.1:65368 - "GET /docs HTTP/1.1" 200
2025-07-20 13:33:36 - App - INFO - 127.0.0.1:65368 - "GET /openapi.json HTTP/1.1" 200
2025-07-20 13:33:53 - App - INFO - 127.0.0.1:65375 - "POST /get_ner_prediction HTTP/1.1" 200
2025-07-20 13:43:57 - App - INFO - 127.0.0.1:49400 - "POST /get_ner_prediction HTTP/1.1" 422
2025-07-20 13:44:08 - App - INFO - 127.0.0.1:49671 - "POST /get_ner_prediction HTTP/1.1" 422
2025-07-20 13:44:45 - App - INFO - 127.0.0.1:49681 - "POST /get_ner_prediction HTTP/1.1" 200
2025-07-20 13:44:46 - App - INFO - 127.0.0.1:49687 - "POST /get_ner_prediction HTTP/1.1" 200
2025-07-20 13:45:18 - App - INFO - Shutting down
2025-07-20 13:45:18 - App - INFO - Finished server process [16496]
2025-07-20 13:45:18 - App - ERROR - Traceback (most recent call last):
  File "C:\Program Files\Python311\Lib\asyncio\runners.py", line 190, in run
    return runner.run(main)
           ^^^^^^^^^^^^^^^^
  File "C:\Program Files\Python311\Lib\asyncio\runners.py", line 118, in run
    return self._loop.run_until_complete(task)
           ^^^^^^^^^^^^^^^^^^^^^^^^^^^^^^^^^^^
  File "C:\Program Files\Python311\Lib\asyncio\base_events.py", line 640, in run_until_complete
    self.run_forever()
  File "C:\Program Files\Python311\Lib\asyncio\windows_events.py", line 321, in run_forever
    super().run_forever()
  File "C:\Program Files\Python311\Lib\asyncio\base_events.py", line 607, in run_forever
    self._run_once()
  File "C:\Program Files\Python311\Lib\asyncio\base_events.py", line 1922, in _run_once
    handle._run()
  File "C:\Program Files\Python311\Lib\asyncio\events.py", line 80, in _run
    self._context.run(self._callback, *self._args)
  File "C:\Users\table\PycharmProjects\MojeCos\venv11\Lib\site-packages\uvicorn\server.py", line 68, in serve
    with self.capture_signals():
  File "C:\Program Files\Python311\Lib\contextlib.py", line 144, in __exit__
    next(self.gen)
  File "C:\Users\table\PycharmProjects\MojeCos\venv11\Lib\site-packages\uvicorn\server.py", line 332, in capture_signals
    signal.raise_signal(captured_signal)
  File "C:\Program Files\Python311\Lib\asyncio\runners.py", line 157, in _on_sigint
    raise KeyboardInterrupt()
KeyboardInterrupt

During handling of the above exception, another exception occurred:

Traceback (most recent call last):
  File "C:\Users\table\PycharmProjects\MojeCos\venv11\Lib\site-packages\starlette\routing.py", line 700, in lifespan
    await receive()
  File "C:\Users\table\PycharmProjects\MojeCos\venv11\Lib\site-packages\uvicorn\lifespan\on.py", line 137, in receive
    return await self.receive_queue.get()
           ^^^^^^^^^^^^^^^^^^^^^^^^^^^^^^
  File "C:\Program Files\Python311\Lib\asyncio\queues.py", line 158, in get
    await getter
asyncio.exceptions.CancelledError

20-07-2025 13:45:27 - middleware_logger - INFO - Line: 28 - Starting api...
20-07-2025 13:45:27 - middleware_logger - INFO - Line: 39 - Api started
2025-07-20 13:45:28 - App - INFO - Started server process [5408]
2025-07-20 13:45:28 - App - INFO - Waiting for application startup.
2025-07-20 13:45:28 - App - INFO - Application startup complete.
2025-07-20 13:45:28 - App - ERROR - [Errno 11001] getaddrinfo failed
2025-07-20 13:45:28 - App - INFO - Waiting for application shutdown.
2025-07-20 13:45:28 - App - INFO - Application shutdown complete.
20-07-2025 13:45:47 - middleware_logger - INFO - Line: 28 - Starting api...
20-07-2025 13:45:47 - middleware_logger - INFO - Line: 39 - Api started
2025-07-20 13:45:47 - App - INFO - Started server process [20084]
2025-07-20 13:45:47 - App - INFO - Waiting for application startup.
2025-07-20 13:45:47 - App - INFO - Application startup complete.
2025-07-20 13:45:47 - App - INFO - Uvicorn running on http://127.0.0.1:5000 (Press CTRL+C to quit)
2025-07-20 13:59:54 - App - INFO - 127.0.0.1:49974 - "POST /get_ner_prediction HTTP/1.1" 200
2025-07-20 14:14:32 - App - INFO - Shutting down
2025-07-20 14:14:33 - App - INFO - Waiting for application shutdown.
2025-07-20 14:14:33 - App - INFO - Application shutdown complete.
2025-07-20 14:14:33 - App - INFO - Finished server process [20084]
20-07-2025 14:14:41 - middleware_logger - INFO - Line: 28 - Starting api...
20-07-2025 14:14:42 - middleware_logger - INFO - Line: 39 - Api started
2025-07-20 14:14:42 - App - INFO - Started server process [6500]
2025-07-20 14:14:42 - App - INFO - Waiting for application startup.
2025-07-20 14:14:42 - App - INFO - Application startup complete.
2025-07-20 14:14:42 - App - INFO - Uvicorn running on http://127.0.0.1:5000 (Press CTRL+C to quit)
2025-07-20 14:14:48 - App - INFO - 127.0.0.1:50396 - "POST /get_ner_prediction HTTP/1.1" 200
2025-07-20 14:45:46 - App - INFO - Shutting down
2025-07-20 14:45:46 - App - INFO - Waiting for application shutdown.
2025-07-20 14:45:46 - App - INFO - Application shutdown complete.
2025-07-20 14:45:46 - App - INFO - Finished server process [6500]
20-07-2025 14:45:55 - middleware_logger - INFO - Line: 28 - Starting api...
20-07-2025 14:45:55 - middleware_logger - INFO - Line: 39 - Api started
2025-07-20 14:45:55 - App - INFO - Started server process [2288]
2025-07-20 14:45:55 - App - INFO - Waiting for application startup.
2025-07-20 14:45:55 - App - INFO - Application startup complete.
2025-07-20 14:45:55 - App - INFO - Uvicorn running on http://127.0.0.1:5000 (Press CTRL+C to quit)
2025-07-20 14:46:10 - App - ERROR - (status code 500) Internal server error 1 validation error for PredictionResponse
tags_count
  Field required [type=missing, input_value={'predictions': [[('the',...], 'predictions_len': 1}, input_type=dict]
    For further information visit https://errors.pydantic.dev/2.5/v/missing
2025-07-20 14:46:10 - App - INFO - 127.0.0.1:50783 - "POST /get_ner_prediction HTTP/1.1" 500
2025-07-20 14:46:10 - App - ERROR - Exception in ASGI application
Traceback (most recent call last):
  File "C:\Users\table\PycharmProjects\MojeCos\ner_fajny\api\routes.py", line 46, in get_ner_prediction
    return PredictionResponse(
           ^^^^^^^^^^^^^^^^^^^
  File "C:\Users\table\PycharmProjects\MojeCos\venv11\Lib\site-packages\pydantic\main.py", line 164, in __init__
    __pydantic_self__.__pydantic_validator__.validate_python(data, self_instance=__pydantic_self__)
pydantic_core._pydantic_core.ValidationError: 1 validation error for PredictionResponse
tags_count
  Field required [type=missing, input_value={'predictions': [[('the',...], 'predictions_len': 1}, input_type=dict]
    For further information visit https://errors.pydantic.dev/2.5/v/missing

During handling of the above exception, another exception occurred:

Traceback (most recent call last):
  File "C:\Users\table\PycharmProjects\MojeCos\venv11\Lib\site-packages\uvicorn\protocols\http\h11_impl.py", line 406, in run_asgi
    result = await app(  # type: ignore[func-returns-value]
             ^^^^^^^^^^^^^^^^^^^^^^^^^^^^^^^^^^^^^^^^^^^^^^
  File "C:\Users\table\PycharmProjects\MojeCos\venv11\Lib\site-packages\uvicorn\middleware\proxy_headers.py", line 60, in __call__
    return await self.app(scope, receive, send)
           ^^^^^^^^^^^^^^^^^^^^^^^^^^^^^^^^^^^^
  File "C:\Users\table\PycharmProjects\MojeCos\venv11\Lib\site-packages\fastapi\applications.py", line 1054, in __call__
    await super().__call__(scope, receive, send)
  File "C:\Users\table\PycharmProjects\MojeCos\venv11\Lib\site-packages\starlette\applications.py", line 113, in __call__
    await self.middleware_stack(scope, receive, send)
  File "C:\Users\table\PycharmProjects\MojeCos\venv11\Lib\site-packages\starlette\middleware\errors.py", line 187, in __call__
    raise exc
  File "C:\Users\table\PycharmProjects\MojeCos\venv11\Lib\site-packages\starlette\middleware\errors.py", line 165, in __call__
    await self.app(scope, receive, _send)
  File "C:\Users\table\PycharmProjects\MojeCos\venv11\Lib\site-packages\starlette\middleware\exceptions.py", line 62, in __call__
    await wrap_app_handling_exceptions(self.app, conn)(scope, receive, send)
  File "C:\Users\table\PycharmProjects\MojeCos\venv11\Lib\site-packages\starlette\_exception_handler.py", line 53, in wrapped_app
    raise exc
  File "C:\Users\table\PycharmProjects\MojeCos\venv11\Lib\site-packages\starlette\_exception_handler.py", line 42, in wrapped_app
    await app(scope, receive, sender)
  File "C:\Users\table\PycharmProjects\MojeCos\venv11\Lib\site-packages\starlette\routing.py", line 715, in __call__
    await self.middleware_stack(scope, receive, send)
  File "C:\Users\table\PycharmProjects\MojeCos\venv11\Lib\site-packages\starlette\routing.py", line 735, in app
    await route.handle(scope, receive, send)
  File "C:\Users\table\PycharmProjects\MojeCos\venv11\Lib\site-packages\starlette\routing.py", line 288, in handle
    await self.app(scope, receive, send)
  File "C:\Users\table\PycharmProjects\MojeCos\venv11\Lib\site-packages\starlette\routing.py", line 76, in app
    await wrap_app_handling_exceptions(app, request)(scope, receive, send)
  File "C:\Users\table\PycharmProjects\MojeCos\venv11\Lib\site-packages\starlette\_exception_handler.py", line 53, in wrapped_app
    raise exc
  File "C:\Users\table\PycharmProjects\MojeCos\venv11\Lib\site-packages\starlette\_exception_handler.py", line 42, in wrapped_app
    await app(scope, receive, sender)
  File "C:\Users\table\PycharmProjects\MojeCos\venv11\Lib\site-packages\starlette\routing.py", line 73, in app
    response = await f(request)
               ^^^^^^^^^^^^^^^^
  File "C:\Users\table\PycharmProjects\MojeCos\venv11\Lib\site-packages\fastapi\routing.py", line 301, in app
    raw_response = await run_endpoint_function(
                   ^^^^^^^^^^^^^^^^^^^^^^^^^^^^
  File "C:\Users\table\PycharmProjects\MojeCos\venv11\Lib\site-packages\fastapi\routing.py", line 212, in run_endpoint_function
    return await dependant.call(**values)
           ^^^^^^^^^^^^^^^^^^^^^^^^^^^^^^
  File "C:\Users\table\PycharmProjects\MojeCos\ner_fajny\api\routes.py", line 56, in get_ner_prediction
    raise HTTPException(status_code=500, detail=f"Internal server error {e}", exc_info=True)
          ^^^^^^^^^^^^^^^^^^^^^^^^^^^^^^^^^^^^^^^^^^^^^^^^^^^^^^^^^^^^^^^^^^^^^^^^^^^^^^^^^^
TypeError: HTTPException.__init__() got an unexpected keyword argument 'exc_info'
2025-07-20 14:47:03 - App - INFO - Shutting down
2025-07-20 14:47:03 - App - INFO - Finished server process [2288]
2025-07-20 14:47:03 - App - ERROR - Traceback (most recent call last):
  File "C:\Program Files\Python311\Lib\asyncio\runners.py", line 190, in run
    return runner.run(main)
           ^^^^^^^^^^^^^^^^
  File "C:\Program Files\Python311\Lib\asyncio\runners.py", line 118, in run
    return self._loop.run_until_complete(task)
           ^^^^^^^^^^^^^^^^^^^^^^^^^^^^^^^^^^^
  File "C:\Program Files\Python311\Lib\asyncio\base_events.py", line 640, in run_until_complete
    self.run_forever()
  File "C:\Program Files\Python311\Lib\asyncio\windows_events.py", line 321, in run_forever
    super().run_forever()
  File "C:\Program Files\Python311\Lib\asyncio\base_events.py", line 607, in run_forever
    self._run_once()
  File "C:\Program Files\Python311\Lib\asyncio\base_events.py", line 1922, in _run_once
    handle._run()
  File "C:\Program Files\Python311\Lib\asyncio\events.py", line 80, in _run
    self._context.run(self._callback, *self._args)
  File "C:\Users\table\PycharmProjects\MojeCos\venv11\Lib\site-packages\uvicorn\server.py", line 68, in serve
    with self.capture_signals():
  File "C:\Program Files\Python311\Lib\contextlib.py", line 144, in __exit__
    next(self.gen)
  File "C:\Users\table\PycharmProjects\MojeCos\venv11\Lib\site-packages\uvicorn\server.py", line 332, in capture_signals
    signal.raise_signal(captured_signal)
  File "C:\Program Files\Python311\Lib\asyncio\runners.py", line 157, in _on_sigint
    raise KeyboardInterrupt()
KeyboardInterrupt

During handling of the above exception, another exception occurred:

Traceback (most recent call last):
  File "C:\Users\table\PycharmProjects\MojeCos\venv11\Lib\site-packages\starlette\routing.py", line 700, in lifespan
    await receive()
  File "C:\Users\table\PycharmProjects\MojeCos\venv11\Lib\site-packages\uvicorn\lifespan\on.py", line 137, in receive
    return await self.receive_queue.get()
           ^^^^^^^^^^^^^^^^^^^^^^^^^^^^^^
  File "C:\Program Files\Python311\Lib\asyncio\queues.py", line 158, in get
    await getter
asyncio.exceptions.CancelledError

20-07-2025 14:47:12 - middleware_logger - INFO - Line: 28 - Starting api...
20-07-2025 14:47:12 - middleware_logger - INFO - Line: 39 - Api started
2025-07-20 14:47:12 - App - INFO - Started server process [10640]
2025-07-20 14:47:12 - App - INFO - Waiting for application startup.
2025-07-20 14:47:12 - App - INFO - Application startup complete.
2025-07-20 14:47:12 - App - INFO - Uvicorn running on http://127.0.0.1:5000 (Press CTRL+C to quit)
2025-07-20 14:47:16 - App - ERROR - (status code 500) Internal server error 1 validation error for PredictionResponse
tags_count
  Field required [type=missing, input_value={'predictions': [[('the',...], 'predictions_len': 1}, input_type=dict]
    For further information visit https://errors.pydantic.dev/2.5/v/missing
Traceback (most recent call last):
  File "C:\Users\table\PycharmProjects\MojeCos\ner_fajny\api\routes.py", line 46, in get_ner_prediction
    return PredictionResponse(
           ^^^^^^^^^^^^^^^^^^^
  File "C:\Users\table\PycharmProjects\MojeCos\venv11\Lib\site-packages\pydantic\main.py", line 164, in __init__
    __pydantic_self__.__pydantic_validator__.validate_python(data, self_instance=__pydantic_self__)
pydantic_core._pydantic_core.ValidationError: 1 validation error for PredictionResponse
tags_count
  Field required [type=missing, input_value={'predictions': [[('the',...], 'predictions_len': 1}, input_type=dict]
    For further information visit https://errors.pydantic.dev/2.5/v/missing
2025-07-20 14:47:16 - App - INFO - 127.0.0.1:50801 - "POST /get_ner_prediction HTTP/1.1" 500
2025-07-20 14:47:45 - App - INFO - Shutting down
2025-07-20 14:47:45 - App - INFO - Finished server process [10640]
2025-07-20 14:47:45 - App - ERROR - Traceback (most recent call last):
  File "C:\Program Files\Python311\Lib\asyncio\runners.py", line 190, in run
    return runner.run(main)
           ^^^^^^^^^^^^^^^^
  File "C:\Program Files\Python311\Lib\asyncio\runners.py", line 118, in run
    return self._loop.run_until_complete(task)
           ^^^^^^^^^^^^^^^^^^^^^^^^^^^^^^^^^^^
  File "C:\Program Files\Python311\Lib\asyncio\base_events.py", line 640, in run_until_complete
    self.run_forever()
  File "C:\Program Files\Python311\Lib\asyncio\windows_events.py", line 321, in run_forever
    super().run_forever()
  File "C:\Program Files\Python311\Lib\asyncio\base_events.py", line 607, in run_forever
    self._run_once()
  File "C:\Program Files\Python311\Lib\asyncio\base_events.py", line 1922, in _run_once
    handle._run()
  File "C:\Program Files\Python311\Lib\asyncio\events.py", line 80, in _run
    self._context.run(self._callback, *self._args)
  File "C:\Users\table\PycharmProjects\MojeCos\venv11\Lib\site-packages\uvicorn\server.py", line 68, in serve
    with self.capture_signals():
  File "C:\Program Files\Python311\Lib\contextlib.py", line 144, in __exit__
    next(self.gen)
  File "C:\Users\table\PycharmProjects\MojeCos\venv11\Lib\site-packages\uvicorn\server.py", line 332, in capture_signals
    signal.raise_signal(captured_signal)
  File "C:\Program Files\Python311\Lib\asyncio\runners.py", line 157, in _on_sigint
    raise KeyboardInterrupt()
KeyboardInterrupt

During handling of the above exception, another exception occurred:

Traceback (most recent call last):
  File "C:\Users\table\PycharmProjects\MojeCos\venv11\Lib\site-packages\starlette\routing.py", line 700, in lifespan
    await receive()
  File "C:\Users\table\PycharmProjects\MojeCos\venv11\Lib\site-packages\uvicorn\lifespan\on.py", line 137, in receive
    return await self.receive_queue.get()
           ^^^^^^^^^^^^^^^^^^^^^^^^^^^^^^
  File "C:\Program Files\Python311\Lib\asyncio\queues.py", line 158, in get
    await getter
asyncio.exceptions.CancelledError

20-07-2025 14:47:54 - middleware_logger - INFO - Line: 28 - Starting api...
20-07-2025 14:47:54 - middleware_logger - INFO - Line: 39 - Api started
2025-07-20 14:47:54 - App - INFO - Started server process [10396]
2025-07-20 14:47:54 - App - INFO - Waiting for application startup.
2025-07-20 14:47:54 - App - INFO - Application startup complete.
2025-07-20 14:47:54 - App - INFO - Uvicorn running on http://127.0.0.1:5000 (Press CTRL+C to quit)
2025-07-20 14:47:58 - App - INFO - 127.0.0.1:50815 - "POST /get_ner_prediction HTTP/1.1" 200
2025-07-20 15:18:06 - App - INFO - Shutting down
2025-07-20 15:18:06 - App - INFO - Waiting for application shutdown.
2025-07-20 15:18:06 - App - INFO - Application shutdown complete.
2025-07-20 15:18:06 - App - INFO - Finished server process [10396]
20-07-2025 23:28:25 - middleware_logger - INFO - Line: 28 - Starting api...
20-07-2025 23:28:26 - middleware_logger - INFO - Line: 39 - Api started
2025-07-20 23:28:26 - App - INFO - Started server process [13344]
2025-07-20 23:28:26 - App - INFO - Waiting for application startup.
2025-07-20 23:28:26 - App - INFO - Application startup complete.
2025-07-20 23:28:26 - App - INFO - Uvicorn running on http://127.0.0.1:5000 (Press CTRL+C to quit)
2025-07-20 23:28:28 - App - INFO - 127.0.0.1:54524 - "GET / HTTP/1.1" 200
2025-07-20 23:28:28 - App - INFO - 127.0.0.1:54524 - "GET /favicon.ico HTTP/1.1" 404
2025-07-20 23:28:30 - App - INFO - 127.0.0.1:54524 - "GET /docs HTTP/1.1" 200
2025-07-20 23:28:31 - App - INFO - 127.0.0.1:54524 - "GET /openapi.json HTTP/1.1" 200
2025-07-20 23:28:38 - App - INFO - 127.0.0.1:54536 - "POST /get_ner_prediction HTTP/1.1" 200
2025-07-20 23:31:58 - App - INFO - Shutting down
2025-07-20 23:31:59 - App - INFO - Waiting for application shutdown.
2025-07-20 23:31:59 - App - INFO - Application shutdown complete.
2025-07-20 23:31:59 - App - INFO - Finished server process [13344]
21-07-2025 23:08:42 - middleware_logger - INFO - Line: 28 - Starting api...
21-07-2025 23:08:42 - middleware_logger - INFO - Line: 39 - Api started
2025-07-21 23:08:42 - App - INFO - Started server process [8388]
2025-07-21 23:08:42 - App - INFO - Waiting for application startup.
2025-07-21 23:08:42 - App - INFO - Application startup complete.
2025-07-21 23:08:42 - App - INFO - Uvicorn running on http://127.0.0.1:5000 (Press CTRL+C to quit)
2025-07-21 23:08:44 - App - INFO - 127.0.0.1:59942 - "GET / HTTP/1.1" 200
2025-07-21 23:08:45 - App - INFO - 127.0.0.1:59942 - "GET /favicon.ico HTTP/1.1" 404
2025-07-21 23:08:47 - App - INFO - 127.0.0.1:59942 - "GET /docs HTTP/1.1" 200
2025-07-21 23:08:47 - App - INFO - 127.0.0.1:59942 - "GET /openapi.json HTTP/1.1" 200
2025-07-21 23:08:56 - App - INFO - 127.0.0.1:59948 - "POST /get_ner_prediction HTTP/1.1" 200
2025-07-21 23:09:28 - App - INFO - 127.0.0.1:59953 - "POST /get_ner_prediction HTTP/1.1" 200
2025-07-21 23:09:55 - App - INFO - Shutting down
2025-07-21 23:09:55 - App - INFO - Finished server process [8388]
2025-07-21 23:09:55 - App - ERROR - Traceback (most recent call last):
  File "C:\Program Files\Python311\Lib\asyncio\runners.py", line 190, in run
    return runner.run(main)
           ^^^^^^^^^^^^^^^^
  File "C:\Program Files\Python311\Lib\asyncio\runners.py", line 118, in run
    return self._loop.run_until_complete(task)
           ^^^^^^^^^^^^^^^^^^^^^^^^^^^^^^^^^^^
  File "C:\Program Files\Python311\Lib\asyncio\base_events.py", line 640, in run_until_complete
    self.run_forever()
  File "C:\Program Files\Python311\Lib\asyncio\windows_events.py", line 321, in run_forever
    super().run_forever()
  File "C:\Program Files\Python311\Lib\asyncio\base_events.py", line 607, in run_forever
    self._run_once()
  File "C:\Program Files\Python311\Lib\asyncio\base_events.py", line 1922, in _run_once
    handle._run()
  File "C:\Program Files\Python311\Lib\asyncio\events.py", line 80, in _run
    self._context.run(self._callback, *self._args)
  File "C:\Users\table\PycharmProjects\MojeCos\venv11\Lib\site-packages\uvicorn\server.py", line 68, in serve
    with self.capture_signals():
  File "C:\Program Files\Python311\Lib\contextlib.py", line 144, in __exit__
    next(self.gen)
  File "C:\Users\table\PycharmProjects\MojeCos\venv11\Lib\site-packages\uvicorn\server.py", line 332, in capture_signals
    signal.raise_signal(captured_signal)
  File "C:\Program Files\Python311\Lib\asyncio\runners.py", line 157, in _on_sigint
    raise KeyboardInterrupt()
KeyboardInterrupt

During handling of the above exception, another exception occurred:

Traceback (most recent call last):
  File "C:\Users\table\PycharmProjects\MojeCos\venv11\Lib\site-packages\starlette\routing.py", line 700, in lifespan
    await receive()
  File "C:\Users\table\PycharmProjects\MojeCos\venv11\Lib\site-packages\uvicorn\lifespan\on.py", line 137, in receive
    return await self.receive_queue.get()
           ^^^^^^^^^^^^^^^^^^^^^^^^^^^^^^
  File "C:\Program Files\Python311\Lib\asyncio\queues.py", line 158, in get
    await getter
asyncio.exceptions.CancelledError

22-07-2025 21:37:14 - middleware_logger - INFO - Line: 28 - Starting api...
22-07-2025 21:37:15 - middleware_logger - INFO - Line: 39 - Api started
2025-07-22 21:37:15 - App - INFO - Started server process [3940]
2025-07-22 21:37:15 - App - INFO - Waiting for application startup.
2025-07-22 21:37:15 - App - INFO - Application startup complete.
2025-07-22 21:37:15 - App - INFO - Uvicorn running on http://127.0.0.1:5000 (Press CTRL+C to quit)
2025-07-22 21:37:55 - App - INFO - 127.0.0.1:52883 - "GET / HTTP/1.1" 200
2025-07-22 21:37:55 - App - INFO - 127.0.0.1:52883 - "GET /favicon.ico HTTP/1.1" 404
2025-07-22 21:37:58 - App - INFO - 127.0.0.1:52883 - "GET /docs HTTP/1.1" 200
2025-07-22 21:37:58 - App - INFO - 127.0.0.1:52883 - "GET /openapi.json HTTP/1.1" 200
2025-07-22 21:42:26 - App - INFO - 127.0.0.1:52949 - "POST /get_ner_prediction HTTP/1.1" 200
2025-07-22 21:51:55 - App - INFO - Shutting down
2025-07-22 21:51:55 - App - INFO - Finished server process [3940]
2025-07-22 21:51:55 - App - ERROR - Traceback (most recent call last):
  File "C:\Program Files\Python311\Lib\asyncio\runners.py", line 190, in run
    return runner.run(main)
           ^^^^^^^^^^^^^^^^
  File "C:\Program Files\Python311\Lib\asyncio\runners.py", line 118, in run
    return self._loop.run_until_complete(task)
           ^^^^^^^^^^^^^^^^^^^^^^^^^^^^^^^^^^^
  File "C:\Program Files\Python311\Lib\asyncio\base_events.py", line 640, in run_until_complete
    self.run_forever()
  File "C:\Program Files\Python311\Lib\asyncio\windows_events.py", line 321, in run_forever
    super().run_forever()
  File "C:\Program Files\Python311\Lib\asyncio\base_events.py", line 607, in run_forever
    self._run_once()
  File "C:\Program Files\Python311\Lib\asyncio\base_events.py", line 1922, in _run_once
    handle._run()
  File "C:\Program Files\Python311\Lib\asyncio\events.py", line 80, in _run
    self._context.run(self._callback, *self._args)
  File "C:\Users\table\PycharmProjects\MojeCos\venv11\Lib\site-packages\uvicorn\server.py", line 68, in serve
    with self.capture_signals():
  File "C:\Program Files\Python311\Lib\contextlib.py", line 144, in __exit__
    next(self.gen)
  File "C:\Users\table\PycharmProjects\MojeCos\venv11\Lib\site-packages\uvicorn\server.py", line 332, in capture_signals
    signal.raise_signal(captured_signal)
  File "C:\Program Files\Python311\Lib\asyncio\runners.py", line 157, in _on_sigint
    raise KeyboardInterrupt()
KeyboardInterrupt

During handling of the above exception, another exception occurred:

Traceback (most recent call last):
  File "C:\Users\table\PycharmProjects\MojeCos\venv11\Lib\site-packages\starlette\routing.py", line 700, in lifespan
    await receive()
  File "C:\Users\table\PycharmProjects\MojeCos\venv11\Lib\site-packages\uvicorn\lifespan\on.py", line 137, in receive
    return await self.receive_queue.get()
           ^^^^^^^^^^^^^^^^^^^^^^^^^^^^^^
  File "C:\Program Files\Python311\Lib\asyncio\queues.py", line 158, in get
    await getter
asyncio.exceptions.CancelledError

24-07-2025 22:13:37 - middleware_logger - INFO - Line: 28 - Starting api...
24-07-2025 22:13:38 - middleware_logger - INFO - Line: 39 - Api started
2025-07-24 22:13:38 - App - INFO - Started server process [7064]
2025-07-24 22:13:38 - App - INFO - Waiting for application startup.
2025-07-24 22:13:38 - App - INFO - Application startup complete.
2025-07-24 22:13:38 - App - INFO - Uvicorn running on http://127.0.0.1:5000 (Press CTRL+C to quit)
2025-07-24 22:13:43 - App - INFO - 127.0.0.1:57897 - "GET / HTTP/1.1" 200
2025-07-24 22:13:43 - App - INFO - 127.0.0.1:57897 - "GET /favicon.ico HTTP/1.1" 404
2025-07-24 22:13:45 - App - INFO - 127.0.0.1:57897 - "GET /docs HTTP/1.1" 200
2025-07-24 22:13:46 - App - INFO - 127.0.0.1:57897 - "GET /openapi.json HTTP/1.1" 200
2025-07-24 22:14:04 - App - INFO - 127.0.0.1:57904 - "POST /get_ner_prediction HTTP/1.1" 200
2025-07-24 22:19:48 - App - INFO - Shutting down
2025-07-24 22:19:48 - App - INFO - Finished server process [7064]
2025-07-24 22:19:48 - App - ERROR - Traceback (most recent call last):
  File "C:\Program Files\Python311\Lib\asyncio\runners.py", line 190, in run
    return runner.run(main)
           ^^^^^^^^^^^^^^^^
  File "C:\Program Files\Python311\Lib\asyncio\runners.py", line 118, in run
    return self._loop.run_until_complete(task)
           ^^^^^^^^^^^^^^^^^^^^^^^^^^^^^^^^^^^
  File "C:\Program Files\Python311\Lib\asyncio\base_events.py", line 640, in run_until_complete
    self.run_forever()
  File "C:\Program Files\Python311\Lib\asyncio\windows_events.py", line 321, in run_forever
    super().run_forever()
  File "C:\Program Files\Python311\Lib\asyncio\base_events.py", line 607, in run_forever
    self._run_once()
  File "C:\Program Files\Python311\Lib\asyncio\base_events.py", line 1922, in _run_once
    handle._run()
  File "C:\Program Files\Python311\Lib\asyncio\events.py", line 80, in _run
    self._context.run(self._callback, *self._args)
  File "C:\Users\table\PycharmProjects\MojeCos\venv11\Lib\site-packages\uvicorn\server.py", line 68, in serve
    with self.capture_signals():
  File "C:\Program Files\Python311\Lib\contextlib.py", line 144, in __exit__
    next(self.gen)
  File "C:\Users\table\PycharmProjects\MojeCos\venv11\Lib\site-packages\uvicorn\server.py", line 332, in capture_signals
    signal.raise_signal(captured_signal)
  File "C:\Program Files\Python311\Lib\asyncio\runners.py", line 157, in _on_sigint
    raise KeyboardInterrupt()
KeyboardInterrupt

During handling of the above exception, another exception occurred:

Traceback (most recent call last):
  File "C:\Users\table\PycharmProjects\MojeCos\venv11\Lib\site-packages\starlette\routing.py", line 700, in lifespan
    await receive()
  File "C:\Users\table\PycharmProjects\MojeCos\venv11\Lib\site-packages\uvicorn\lifespan\on.py", line 137, in receive
    return await self.receive_queue.get()
           ^^^^^^^^^^^^^^^^^^^^^^^^^^^^^^
  File "C:\Program Files\Python311\Lib\asyncio\queues.py", line 158, in get
    await getter
asyncio.exceptions.CancelledError

24-07-2025 22:19:57 - middleware_logger - INFO - Line: 28 - Starting api...
24-07-2025 22:19:57 - middleware_logger - INFO - Line: 39 - Api started
2025-07-24 22:19:57 - App - INFO - Started server process [9020]
2025-07-24 22:19:57 - App - INFO - Waiting for application startup.
2025-07-24 22:19:57 - App - INFO - Application startup complete.
2025-07-24 22:19:57 - App - INFO - Uvicorn running on http://127.0.0.1:5000 (Press CTRL+C to quit)
2025-07-24 22:20:13 - App - INFO - 127.0.0.1:57946 - "GET / HTTP/1.1" 200
2025-07-24 22:20:19 - App - ERROR - (status code 500) Internal server error 'list' object has no attribute 'items'
Traceback (most recent call last):
  File "C:\Users\table\PycharmProjects\MojeCos\ner_fajny\api\routes.py", line 80, in get_ner_prediction
    human_readble_tags_counters = {Config.HUMAN_READABLE_TAGS_MAP.get(key, key): value for key, value in tags_counters.items()}
                                                                                                         ^^^^^^^^^^^^^^^^^^^
AttributeError: 'list' object has no attribute 'items'
2025-07-24 22:20:19 - App - INFO - 127.0.0.1:57946 - "POST /get_ner_prediction HTTP/1.1" 500
2025-07-24 22:23:58 - App - INFO - Shutting down
2025-07-24 22:23:58 - App - INFO - Finished server process [9020]
2025-07-24 22:23:58 - App - ERROR - Traceback (most recent call last):
  File "C:\Program Files\Python311\Lib\asyncio\runners.py", line 190, in run
    return runner.run(main)
           ^^^^^^^^^^^^^^^^
  File "C:\Program Files\Python311\Lib\asyncio\runners.py", line 118, in run
    return self._loop.run_until_complete(task)
           ^^^^^^^^^^^^^^^^^^^^^^^^^^^^^^^^^^^
  File "C:\Program Files\Python311\Lib\asyncio\base_events.py", line 640, in run_until_complete
    self.run_forever()
  File "C:\Program Files\Python311\Lib\asyncio\windows_events.py", line 321, in run_forever
    super().run_forever()
  File "C:\Program Files\Python311\Lib\asyncio\base_events.py", line 607, in run_forever
    self._run_once()
  File "C:\Program Files\Python311\Lib\asyncio\base_events.py", line 1922, in _run_once
    handle._run()
  File "C:\Program Files\Python311\Lib\asyncio\events.py", line 80, in _run
    self._context.run(self._callback, *self._args)
  File "C:\Users\table\PycharmProjects\MojeCos\venv11\Lib\site-packages\uvicorn\server.py", line 68, in serve
    with self.capture_signals():
  File "C:\Program Files\Python311\Lib\contextlib.py", line 144, in __exit__
    next(self.gen)
  File "C:\Users\table\PycharmProjects\MojeCos\venv11\Lib\site-packages\uvicorn\server.py", line 332, in capture_signals
    signal.raise_signal(captured_signal)
  File "C:\Program Files\Python311\Lib\asyncio\runners.py", line 157, in _on_sigint
    raise KeyboardInterrupt()
KeyboardInterrupt

During handling of the above exception, another exception occurred:

Traceback (most recent call last):
  File "C:\Users\table\PycharmProjects\MojeCos\venv11\Lib\site-packages\starlette\routing.py", line 700, in lifespan
    await receive()
  File "C:\Users\table\PycharmProjects\MojeCos\venv11\Lib\site-packages\uvicorn\lifespan\on.py", line 137, in receive
    return await self.receive_queue.get()
           ^^^^^^^^^^^^^^^^^^^^^^^^^^^^^^
  File "C:\Program Files\Python311\Lib\asyncio\queues.py", line 158, in get
    await getter
asyncio.exceptions.CancelledError

24-07-2025 22:24:07 - middleware_logger - INFO - Line: 28 - Starting api...
24-07-2025 22:24:07 - middleware_logger - INFO - Line: 39 - Api started
2025-07-24 22:24:07 - App - INFO - Started server process [10652]
2025-07-24 22:24:07 - App - INFO - Waiting for application startup.
2025-07-24 22:24:07 - App - INFO - Application startup complete.
2025-07-24 22:24:07 - App - INFO - Uvicorn running on http://127.0.0.1:5000 (Press CTRL+C to quit)
2025-07-24 22:24:15 - App - ERROR - (status code 500) Internal server error 6 validation errors for PredictionResponse
human_readble_grouped_by_tags.0.O
  Input should be a valid list [type=list_type, input_value=10, input_type=int]
    For further information visit https://errors.pydantic.dev/2.5/v/list_type
human_readble_grouped_by_tags.0.B-org
  Input should be a valid list [type=list_type, input_value=3, input_type=int]
    For further information visit https://errors.pydantic.dev/2.5/v/list_type
human_readble_grouped_by_tags.1.B-gpe
  Input should be a valid list [type=list_type, input_value=1, input_type=int]
    For further information visit https://errors.pydantic.dev/2.5/v/list_type
human_readble_grouped_by_tags.1.O
  Input should be a valid list [type=list_type, input_value=9, input_type=int]
    For further information visit https://errors.pydantic.dev/2.5/v/list_type
human_readble_grouped_by_tags.1.B-geo
  Input should be a valid list [type=list_type, input_value=1, input_type=int]
    For further information visit https://errors.pydantic.dev/2.5/v/list_type
human_readble_grouped_by_tags.2.O
  Input should be a valid list [type=list_type, input_value=5, input_type=int]
    For further information visit https://errors.pydantic.dev/2.5/v/list_type
Traceback (most recent call last):
  File "C:\Users\table\PycharmProjects\MojeCos\ner_fajny\api\routes.py", line 87, in get_ner_prediction
    return PredictionResponse(
           ^^^^^^^^^^^^^^^^^^^
  File "C:\Users\table\PycharmProjects\MojeCos\venv11\Lib\site-packages\pydantic\main.py", line 164, in __init__
    __pydantic_self__.__pydantic_validator__.validate_python(data, self_instance=__pydantic_self__)
pydantic_core._pydantic_core.ValidationError: 6 validation errors for PredictionResponse
human_readble_grouped_by_tags.0.O
  Input should be a valid list [type=list_type, input_value=10, input_type=int]
    For further information visit https://errors.pydantic.dev/2.5/v/list_type
human_readble_grouped_by_tags.0.B-org
  Input should be a valid list [type=list_type, input_value=3, input_type=int]
    For further information visit https://errors.pydantic.dev/2.5/v/list_type
human_readble_grouped_by_tags.1.B-gpe
  Input should be a valid list [type=list_type, input_value=1, input_type=int]
    For further information visit https://errors.pydantic.dev/2.5/v/list_type
human_readble_grouped_by_tags.1.O
  Input should be a valid list [type=list_type, input_value=9, input_type=int]
    For further information visit https://errors.pydantic.dev/2.5/v/list_type
human_readble_grouped_by_tags.1.B-geo
  Input should be a valid list [type=list_type, input_value=1, input_type=int]
    For further information visit https://errors.pydantic.dev/2.5/v/list_type
human_readble_grouped_by_tags.2.O
  Input should be a valid list [type=list_type, input_value=5, input_type=int]
    For further information visit https://errors.pydantic.dev/2.5/v/list_type
2025-07-24 22:24:15 - App - INFO - 127.0.0.1:57972 - "POST /get_ner_prediction HTTP/1.1" 500
2025-07-24 22:26:01 - App - INFO - Shutting down
2025-07-24 22:26:01 - App - INFO - Finished server process [10652]
2025-07-24 22:26:01 - App - ERROR - Traceback (most recent call last):
  File "C:\Program Files\Python311\Lib\asyncio\runners.py", line 190, in run
    return runner.run(main)
           ^^^^^^^^^^^^^^^^
  File "C:\Program Files\Python311\Lib\asyncio\runners.py", line 118, in run
    return self._loop.run_until_complete(task)
           ^^^^^^^^^^^^^^^^^^^^^^^^^^^^^^^^^^^
  File "C:\Program Files\Python311\Lib\asyncio\base_events.py", line 640, in run_until_complete
    self.run_forever()
  File "C:\Program Files\Python311\Lib\asyncio\windows_events.py", line 321, in run_forever
    super().run_forever()
  File "C:\Program Files\Python311\Lib\asyncio\base_events.py", line 607, in run_forever
    self._run_once()
  File "C:\Program Files\Python311\Lib\asyncio\base_events.py", line 1922, in _run_once
    handle._run()
  File "C:\Program Files\Python311\Lib\asyncio\events.py", line 80, in _run
    self._context.run(self._callback, *self._args)
  File "C:\Users\table\PycharmProjects\MojeCos\venv11\Lib\site-packages\uvicorn\server.py", line 68, in serve
    with self.capture_signals():
  File "C:\Program Files\Python311\Lib\contextlib.py", line 144, in __exit__
    next(self.gen)
  File "C:\Users\table\PycharmProjects\MojeCos\venv11\Lib\site-packages\uvicorn\server.py", line 332, in capture_signals
    signal.raise_signal(captured_signal)
  File "C:\Program Files\Python311\Lib\asyncio\runners.py", line 157, in _on_sigint
    raise KeyboardInterrupt()
KeyboardInterrupt

During handling of the above exception, another exception occurred:

Traceback (most recent call last):
  File "C:\Users\table\PycharmProjects\MojeCos\venv11\Lib\site-packages\starlette\routing.py", line 700, in lifespan
    await receive()
  File "C:\Users\table\PycharmProjects\MojeCos\venv11\Lib\site-packages\uvicorn\lifespan\on.py", line 137, in receive
    return await self.receive_queue.get()
           ^^^^^^^^^^^^^^^^^^^^^^^^^^^^^^
  File "C:\Program Files\Python311\Lib\asyncio\queues.py", line 158, in get
    await getter
asyncio.exceptions.CancelledError

24-07-2025 22:26:09 - middleware_logger - INFO - Line: 28 - Starting api...
24-07-2025 22:26:10 - middleware_logger - INFO - Line: 39 - Api started
2025-07-24 22:26:10 - App - INFO - Started server process [17228]
2025-07-24 22:26:10 - App - INFO - Waiting for application startup.
2025-07-24 22:26:10 - App - INFO - Application startup complete.
2025-07-24 22:26:10 - App - INFO - Uvicorn running on http://127.0.0.1:5000 (Press CTRL+C to quit)
2025-07-24 22:26:13 - App - ERROR - (status code 500) Internal server error 'list' object has no attribute 'items'
Traceback (most recent call last):
  File "C:\Users\table\PycharmProjects\MojeCos\ner_fajny\api\routes.py", line 87, in get_ner_prediction
    {Config.HUMAN_READABLE_TAGS_MAP.get(key, key): value for key, value in grouped_by_tags.items()}
                                                                           ^^^^^^^^^^^^^^^^^^^^^
AttributeError: 'list' object has no attribute 'items'
2025-07-24 22:26:13 - App - INFO - 127.0.0.1:57988 - "POST /get_ner_prediction HTTP/1.1" 500
2025-07-24 22:26:27 - App - INFO - Shutting down
2025-07-24 22:26:27 - App - INFO - Waiting for application shutdown.
2025-07-24 22:26:27 - App - INFO - Application shutdown complete.
2025-07-24 22:26:27 - App - INFO - Finished server process [17228]
24-07-2025 22:26:35 - middleware_logger - INFO - Line: 28 - Starting api...
24-07-2025 22:26:36 - middleware_logger - INFO - Line: 39 - Api started
2025-07-24 22:26:36 - App - INFO - Started server process [5416]
2025-07-24 22:26:36 - App - INFO - Waiting for application startup.
2025-07-24 22:26:36 - App - INFO - Application startup complete.
2025-07-24 22:26:36 - App - INFO - Uvicorn running on http://127.0.0.1:5000 (Press CTRL+C to quit)
2025-07-24 22:26:38 - App - ERROR - (status code 500) Internal server error 1 validation error for PredictionResponse
human_readble_grouped_by_tags
  Field required [type=missing, input_value={'predictions': [[('the',...ocations': ['us']}, {}]}, input_type=dict]
    For further information visit https://errors.pydantic.dev/2.5/v/missing
Traceback (most recent call last):
  File "C:\Users\table\PycharmProjects\MojeCos\ner_fajny\api\routes.py", line 89, in get_ner_prediction
    return PredictionResponse(
           ^^^^^^^^^^^^^^^^^^^
  File "C:\Users\table\PycharmProjects\MojeCos\venv11\Lib\site-packages\pydantic\main.py", line 164, in __init__
    __pydantic_self__.__pydantic_validator__.validate_python(data, self_instance=__pydantic_self__)
pydantic_core._pydantic_core.ValidationError: 1 validation error for PredictionResponse
human_readble_grouped_by_tags
  Field required [type=missing, input_value={'predictions': [[('the',...ocations': ['us']}, {}]}, input_type=dict]
    For further information visit https://errors.pydantic.dev/2.5/v/missing
2025-07-24 22:26:38 - App - INFO - 127.0.0.1:57995 - "POST /get_ner_prediction HTTP/1.1" 500
2025-07-24 22:27:06 - App - INFO - Shutting down
2025-07-24 22:27:06 - App - INFO - Finished server process [5416]
2025-07-24 22:27:06 - App - ERROR - Traceback (most recent call last):
  File "C:\Program Files\Python311\Lib\asyncio\runners.py", line 190, in run
    return runner.run(main)
           ^^^^^^^^^^^^^^^^
  File "C:\Program Files\Python311\Lib\asyncio\runners.py", line 118, in run
    return self._loop.run_until_complete(task)
           ^^^^^^^^^^^^^^^^^^^^^^^^^^^^^^^^^^^
  File "C:\Program Files\Python311\Lib\asyncio\base_events.py", line 640, in run_until_complete
    self.run_forever()
  File "C:\Program Files\Python311\Lib\asyncio\windows_events.py", line 321, in run_forever
    super().run_forever()
  File "C:\Program Files\Python311\Lib\asyncio\base_events.py", line 607, in run_forever
    self._run_once()
  File "C:\Program Files\Python311\Lib\asyncio\base_events.py", line 1922, in _run_once
    handle._run()
  File "C:\Program Files\Python311\Lib\asyncio\events.py", line 80, in _run
    self._context.run(self._callback, *self._args)
  File "C:\Users\table\PycharmProjects\MojeCos\venv11\Lib\site-packages\uvicorn\server.py", line 68, in serve
    with self.capture_signals():
  File "C:\Program Files\Python311\Lib\contextlib.py", line 144, in __exit__
    next(self.gen)
  File "C:\Users\table\PycharmProjects\MojeCos\venv11\Lib\site-packages\uvicorn\server.py", line 332, in capture_signals
    signal.raise_signal(captured_signal)
  File "C:\Program Files\Python311\Lib\asyncio\runners.py", line 157, in _on_sigint
    raise KeyboardInterrupt()
KeyboardInterrupt

During handling of the above exception, another exception occurred:

Traceback (most recent call last):
  File "C:\Users\table\PycharmProjects\MojeCos\venv11\Lib\site-packages\starlette\routing.py", line 700, in lifespan
    await receive()
  File "C:\Users\table\PycharmProjects\MojeCos\venv11\Lib\site-packages\uvicorn\lifespan\on.py", line 137, in receive
    return await self.receive_queue.get()
           ^^^^^^^^^^^^^^^^^^^^^^^^^^^^^^
  File "C:\Program Files\Python311\Lib\asyncio\queues.py", line 158, in get
    await getter
asyncio.exceptions.CancelledError

24-07-2025 22:27:15 - middleware_logger - INFO - Line: 28 - Starting api...
24-07-2025 22:27:15 - middleware_logger - INFO - Line: 39 - Api started
2025-07-24 22:27:15 - App - INFO - Started server process [2356]
2025-07-24 22:27:15 - App - INFO - Waiting for application startup.
2025-07-24 22:27:15 - App - INFO - Application startup complete.
2025-07-24 22:27:15 - App - INFO - Uvicorn running on http://127.0.0.1:5000 (Press CTRL+C to quit)
2025-07-24 22:27:19 - App - INFO - 127.0.0.1:58003 - "POST /get_ner_prediction HTTP/1.1" 200
2025-07-24 23:05:11 - App - INFO - Shutting down
2025-07-24 23:05:11 - App - INFO - Finished server process [2356]
2025-07-24 23:05:11 - App - ERROR - Traceback (most recent call last):
  File "C:\Program Files\Python311\Lib\asyncio\runners.py", line 190, in run
    return runner.run(main)
           ^^^^^^^^^^^^^^^^
  File "C:\Program Files\Python311\Lib\asyncio\runners.py", line 118, in run
    return self._loop.run_until_complete(task)
           ^^^^^^^^^^^^^^^^^^^^^^^^^^^^^^^^^^^
  File "C:\Program Files\Python311\Lib\asyncio\base_events.py", line 640, in run_until_complete
    self.run_forever()
  File "C:\Program Files\Python311\Lib\asyncio\windows_events.py", line 321, in run_forever
    super().run_forever()
  File "C:\Program Files\Python311\Lib\asyncio\base_events.py", line 607, in run_forever
    self._run_once()
  File "C:\Program Files\Python311\Lib\asyncio\base_events.py", line 1922, in _run_once
    handle._run()
  File "C:\Program Files\Python311\Lib\asyncio\events.py", line 80, in _run
    self._context.run(self._callback, *self._args)
  File "C:\Users\table\PycharmProjects\MojeCos\venv11\Lib\site-packages\uvicorn\server.py", line 68, in serve
    with self.capture_signals():
  File "C:\Program Files\Python311\Lib\contextlib.py", line 144, in __exit__
    next(self.gen)
  File "C:\Users\table\PycharmProjects\MojeCos\venv11\Lib\site-packages\uvicorn\server.py", line 332, in capture_signals
    signal.raise_signal(captured_signal)
  File "C:\Program Files\Python311\Lib\asyncio\runners.py", line 157, in _on_sigint
    raise KeyboardInterrupt()
KeyboardInterrupt

During handling of the above exception, another exception occurred:

Traceback (most recent call last):
  File "C:\Users\table\PycharmProjects\MojeCos\venv11\Lib\site-packages\starlette\routing.py", line 700, in lifespan
    await receive()
  File "C:\Users\table\PycharmProjects\MojeCos\venv11\Lib\site-packages\uvicorn\lifespan\on.py", line 137, in receive
    return await self.receive_queue.get()
           ^^^^^^^^^^^^^^^^^^^^^^^^^^^^^^
  File "C:\Program Files\Python311\Lib\asyncio\queues.py", line 158, in get
    await getter
asyncio.exceptions.CancelledError

25-07-2025 22:43:00 - middleware_logger - INFO - Line: 28 - Starting api...
25-07-2025 22:43:01 - middleware_logger - INFO - Line: 39 - Api started
2025-07-25 22:43:01 - App - INFO - Started server process [23696]
2025-07-25 22:43:01 - App - INFO - Waiting for application startup.
2025-07-25 22:43:01 - App - INFO - Application startup complete.
2025-07-25 22:43:01 - App - INFO - Uvicorn running on http://127.0.0.1:5000 (Press CTRL+C to quit)
2025-07-25 22:43:20 - App - INFO - 127.0.0.1:62366 - "GET / HTTP/1.1" 200
2025-07-25 22:43:20 - App - INFO - 127.0.0.1:62366 - "GET /favicon.ico HTTP/1.1" 404
2025-07-25 22:43:24 - App - INFO - 127.0.0.1:62366 - "GET /docs HTTP/1.1" 200
2025-07-25 22:43:24 - App - INFO - 127.0.0.1:62366 - "GET /openapi.json HTTP/1.1" 200
2025-07-25 22:44:19 - App - INFO - 127.0.0.1:62378 - "POST /get_ner_prediction HTTP/1.1" 200
2025-07-25 22:53:30 - App - INFO - Shutting down
2025-07-25 22:53:30 - App - INFO - Finished server process [23696]
2025-07-25 22:53:30 - App - ERROR - Traceback (most recent call last):
  File "C:\Program Files\Python311\Lib\asyncio\runners.py", line 190, in run
    return runner.run(main)
           ^^^^^^^^^^^^^^^^
  File "C:\Program Files\Python311\Lib\asyncio\runners.py", line 118, in run
    return self._loop.run_until_complete(task)
           ^^^^^^^^^^^^^^^^^^^^^^^^^^^^^^^^^^^
  File "C:\Program Files\Python311\Lib\asyncio\base_events.py", line 640, in run_until_complete
    self.run_forever()
  File "C:\Program Files\Python311\Lib\asyncio\windows_events.py", line 321, in run_forever
    super().run_forever()
  File "C:\Program Files\Python311\Lib\asyncio\base_events.py", line 607, in run_forever
    self._run_once()
  File "C:\Program Files\Python311\Lib\asyncio\base_events.py", line 1922, in _run_once
    handle._run()
  File "C:\Program Files\Python311\Lib\asyncio\events.py", line 80, in _run
    self._context.run(self._callback, *self._args)
  File "C:\Users\table\PycharmProjects\MojeCos\venv11\Lib\site-packages\uvicorn\server.py", line 68, in serve
    with self.capture_signals():
  File "C:\Program Files\Python311\Lib\contextlib.py", line 144, in __exit__
    next(self.gen)
  File "C:\Users\table\PycharmProjects\MojeCos\venv11\Lib\site-packages\uvicorn\server.py", line 332, in capture_signals
    signal.raise_signal(captured_signal)
  File "C:\Program Files\Python311\Lib\asyncio\runners.py", line 157, in _on_sigint
    raise KeyboardInterrupt()
KeyboardInterrupt

During handling of the above exception, another exception occurred:

Traceback (most recent call last):
  File "C:\Users\table\PycharmProjects\MojeCos\venv11\Lib\site-packages\starlette\routing.py", line 700, in lifespan
    await receive()
  File "C:\Users\table\PycharmProjects\MojeCos\venv11\Lib\site-packages\uvicorn\lifespan\on.py", line 137, in receive
    return await self.receive_queue.get()
           ^^^^^^^^^^^^^^^^^^^^^^^^^^^^^^
  File "C:\Program Files\Python311\Lib\asyncio\queues.py", line 158, in get
    await getter
asyncio.exceptions.CancelledError

25-07-2025 23:14:02 - middleware_logger - INFO - Line: 28 - Starting api...
25-07-2025 23:14:02 - middleware_logger - INFO - Line: 39 - Api started
2025-07-25 23:14:02 - App - INFO - Started server process [13052]
2025-07-25 23:14:02 - App - INFO - Waiting for application startup.
2025-07-25 23:14:02 - App - INFO - Application startup complete.
2025-07-25 23:14:02 - App - INFO - Uvicorn running on http://127.0.0.1:5000 (Press CTRL+C to quit)
2025-07-25 23:14:06 - App - INFO - 127.0.0.1:50291 - "GET / HTTP/1.1" 200
2025-07-25 23:14:06 - App - INFO - 127.0.0.1:50291 - "GET /favicon.ico HTTP/1.1" 404
2025-07-25 23:14:08 - App - INFO - 127.0.0.1:50291 - "GET /docs HTTP/1.1" 200
2025-07-25 23:14:08 - App - INFO - 127.0.0.1:50291 - "GET /openapi.json HTTP/1.1" 200
2025-07-25 23:14:29 - App - INFO - 127.0.0.1:50311 - "POST /get_ner_prediction HTTP/1.1" 200
2025-07-25 23:15:36 - App - INFO - Shutting down
2025-07-25 23:15:36 - App - INFO - Finished server process [13052]
2025-07-25 23:15:36 - App - ERROR - Traceback (most recent call last):
  File "C:\Program Files\Python311\Lib\asyncio\runners.py", line 190, in run
    return runner.run(main)
           ^^^^^^^^^^^^^^^^
  File "C:\Program Files\Python311\Lib\asyncio\runners.py", line 118, in run
    return self._loop.run_until_complete(task)
           ^^^^^^^^^^^^^^^^^^^^^^^^^^^^^^^^^^^
  File "C:\Program Files\Python311\Lib\asyncio\base_events.py", line 640, in run_until_complete
    self.run_forever()
  File "C:\Program Files\Python311\Lib\asyncio\windows_events.py", line 321, in run_forever
    super().run_forever()
  File "C:\Program Files\Python311\Lib\asyncio\base_events.py", line 607, in run_forever
    self._run_once()
  File "C:\Program Files\Python311\Lib\asyncio\base_events.py", line 1922, in _run_once
    handle._run()
  File "C:\Program Files\Python311\Lib\asyncio\events.py", line 80, in _run
    self._context.run(self._callback, *self._args)
  File "C:\Users\table\PycharmProjects\MojeCos\venv11\Lib\site-packages\uvicorn\server.py", line 68, in serve
    with self.capture_signals():
  File "C:\Program Files\Python311\Lib\contextlib.py", line 144, in __exit__
    next(self.gen)
  File "C:\Users\table\PycharmProjects\MojeCos\venv11\Lib\site-packages\uvicorn\server.py", line 332, in capture_signals
    signal.raise_signal(captured_signal)
  File "C:\Program Files\Python311\Lib\asyncio\runners.py", line 157, in _on_sigint
    raise KeyboardInterrupt()
KeyboardInterrupt

During handling of the above exception, another exception occurred:

Traceback (most recent call last):
  File "C:\Users\table\PycharmProjects\MojeCos\venv11\Lib\site-packages\starlette\routing.py", line 700, in lifespan
    await receive()
  File "C:\Users\table\PycharmProjects\MojeCos\venv11\Lib\site-packages\uvicorn\lifespan\on.py", line 137, in receive
    return await self.receive_queue.get()
           ^^^^^^^^^^^^^^^^^^^^^^^^^^^^^^
  File "C:\Program Files\Python311\Lib\asyncio\queues.py", line 158, in get
    await getter
asyncio.exceptions.CancelledError

26-07-2025 13:37:22 - middleware_logger - INFO - Line: 28 - Starting api...
26-07-2025 13:37:23 - middleware_logger - INFO - Line: 39 - Api started
2025-07-26 13:37:23 - App - INFO - Started server process [11932]
2025-07-26 13:37:23 - App - INFO - Waiting for application startup.
2025-07-26 13:37:23 - App - INFO - Application startup complete.
2025-07-26 13:37:23 - App - INFO - Uvicorn running on http://127.0.0.1:5000 (Press CTRL+C to quit)
2025-07-26 13:37:35 - App - INFO - 127.0.0.1:54142 - "GET / HTTP/1.1" 200
2025-07-26 13:37:35 - App - INFO - 127.0.0.1:54142 - "GET /favicon.ico HTTP/1.1" 404
2025-07-26 13:37:38 - App - INFO - 127.0.0.1:54142 - "GET /docs HTTP/1.1" 200
2025-07-26 13:37:38 - App - INFO - 127.0.0.1:54142 - "GET /openapi.json HTTP/1.1" 200
2025-07-26 13:40:36 - App - INFO - Shutting down
2025-07-26 13:40:36 - App - INFO - Waiting for application shutdown.
2025-07-26 13:40:36 - App - INFO - Application shutdown complete.
2025-07-26 13:40:36 - App - INFO - Finished server process [11932]
26-07-2025 13:40:46 - middleware_logger - INFO - Line: 28 - Starting api...
26-07-2025 13:40:47 - middleware_logger - INFO - Line: 39 - Api started
2025-07-26 13:40:47 - App - INFO - Started server process [13316]
2025-07-26 13:40:47 - App - INFO - Waiting for application startup.
2025-07-26 13:40:47 - App - INFO - Application startup complete.
2025-07-26 13:40:47 - App - INFO - Uvicorn running on http://127.0.0.1:5000 (Press CTRL+C to quit)
2025-07-26 13:41:15 - App - INFO - 127.0.0.1:54226 - "GET /docs HTTP/1.1" 200
2025-07-26 13:41:15 - App - INFO - 127.0.0.1:54226 - "GET /openapi.json HTTP/1.1" 200
2025-07-26 13:41:21 - App - INFO - 127.0.0.1:54229 - "GET /health HTTP/1.1" 200
2025-07-26 13:41:24 - App - INFO - 127.0.0.1:54229 - "GET / HTTP/1.1" 200
2025-07-26 13:49:08 - App - INFO - 127.0.0.1:54427 - "POST /get_ner_prediction HTTP/1.1" 200
2025-07-26 14:02:08 - App - INFO - 127.0.0.1:54704 - "POST /get_ner_prediction HTTP/1.1" 200
2025-07-26 14:02:12 - App - INFO - 127.0.0.1:54710 - "POST /get_ner_prediction HTTP/1.1" 200
2025-07-26 14:02:22 - App - INFO - 127.0.0.1:54720 - "POST /get_ner_prediction HTTP/1.1" 200
2025-07-26 14:05:06 - App - INFO - 127.0.0.1:54752 - "GET /docs HTTP/1.1" 200
2025-07-26 14:05:06 - App - INFO - 127.0.0.1:54752 - "GET /openapi.json HTTP/1.1" 200
2025-07-26 14:11:54 - App - INFO - 127.0.0.1:54916 - "POST /get_ner_prediction HTTP/1.1" 200
2025-07-26 14:15:20 - App - INFO - 127.0.0.1:55019 - "POST /get_ner_prediction HTTP/1.1" 200
2025-07-26 14:19:50 - App - INFO - 127.0.0.1:55060 - "POST /get_ner_prediction HTTP/1.1" 200
2025-07-26 14:22:16 - App - INFO - 127.0.0.1:55159 - "POST /get_ner_prediction HTTP/1.1" 200
2025-07-26 14:25:52 - App - INFO - 127.0.0.1:55216 - "POST /get_ner_prediction HTTP/1.1" 200
2025-07-26 14:32:30 - App - INFO - 127.0.0.1:55322 - "POST /get_ner_prediction HTTP/1.1" 200
2025-07-26 14:33:22 - App - INFO - 127.0.0.1:55331 - "POST /get_ner_prediction HTTP/1.1" 200
2025-07-26 14:33:31 - App - INFO - 127.0.0.1:55339 - "POST /get_ner_prediction HTTP/1.1" 200
2025-07-26 14:34:45 - App - INFO - 127.0.0.1:55369 - "POST /get_ner_prediction HTTP/1.1" 200
2025-07-26 14:35:04 - App - INFO - 127.0.0.1:55377 - "POST /get_ner_prediction HTTP/1.1" 200
2025-07-26 14:35:14 - App - INFO - 127.0.0.1:55385 - "POST /get_ner_prediction HTTP/1.1" 200
2025-07-26 14:35:55 - App - INFO - 127.0.0.1:55394 - "POST /get_ner_prediction HTTP/1.1" 200
2025-07-26 14:36:15 - App - INFO - 127.0.0.1:55404 - "POST /get_ner_prediction HTTP/1.1" 200
2025-07-26 14:36:23 - App - INFO - 127.0.0.1:55412 - "POST /get_ner_prediction HTTP/1.1" 200
2025-07-26 14:36:36 - App - INFO - 127.0.0.1:55418 - "POST /get_ner_prediction HTTP/1.1" 200
2025-07-26 14:36:55 - App - INFO - 127.0.0.1:55427 - "POST /get_ner_prediction HTTP/1.1" 200
2025-07-26 14:37:05 - App - INFO - 127.0.0.1:55433 - "POST /get_ner_prediction HTTP/1.1" 200
2025-07-26 14:37:11 - App - INFO - 127.0.0.1:55439 - "POST /get_ner_prediction HTTP/1.1" 200
2025-07-26 14:37:17 - App - INFO - 127.0.0.1:55447 - "POST /get_ner_prediction HTTP/1.1" 200
2025-07-26 14:37:40 - App - INFO - 127.0.0.1:55458 - "POST /get_ner_prediction HTTP/1.1" 200
2025-07-26 14:37:56 - App - INFO - 127.0.0.1:55464 - "POST /get_ner_prediction HTTP/1.1" 200
2025-07-26 14:38:01 - App - INFO - 127.0.0.1:55471 - "POST /get_ner_prediction HTTP/1.1" 200
2025-07-26 14:38:21 - App - INFO - 127.0.0.1:55478 - "POST /get_ner_prediction HTTP/1.1" 200
2025-07-26 14:38:29 - App - INFO - 127.0.0.1:55484 - "POST /get_ner_prediction HTTP/1.1" 200
2025-07-26 14:38:49 - App - INFO - 127.0.0.1:55490 - "POST /get_ner_prediction HTTP/1.1" 200
2025-07-26 14:39:01 - App - INFO - 127.0.0.1:55497 - "POST /get_ner_prediction HTTP/1.1" 200
2025-07-26 14:39:11 - App - INFO - 127.0.0.1:55505 - "POST /get_ner_prediction HTTP/1.1" 200
2025-07-26 14:43:03 - App - INFO - 127.0.0.1:55611 - "POST /get_ner_prediction HTTP/1.1" 200
2025-07-26 14:45:25 - App - INFO - 127.0.0.1:55645 - "POST /get_ner_prediction HTTP/1.1" 200
2025-07-26 14:46:07 - App - INFO - 127.0.0.1:55654 - "POST /get_ner_prediction HTTP/1.1" 200
2025-07-26 14:48:35 - App - INFO - 127.0.0.1:55691 - "POST /get_ner_prediction HTTP/1.1" 200
2025-07-26 14:49:43 - App - INFO - 127.0.0.1:55709 - "POST /get_ner_prediction HTTP/1.1" 200
2025-07-26 14:51:45 - App - INFO - 127.0.0.1:55734 - "POST /get_ner_prediction HTTP/1.1" 200
2025-07-26 14:53:05 - App - INFO - 127.0.0.1:55758 - "POST /get_ner_prediction HTTP/1.1" 200
2025-07-26 14:53:29 - App - INFO - 127.0.0.1:55768 - "POST /get_ner_prediction HTTP/1.1" 200
2025-07-26 14:54:08 - App - INFO - 127.0.0.1:55778 - "POST /get_ner_prediction HTTP/1.1" 200
2025-07-26 14:54:13 - App - INFO - 127.0.0.1:55785 - "POST /get_ner_prediction HTTP/1.1" 200
2025-07-26 14:54:20 - App - INFO - 127.0.0.1:55792 - "POST /get_ner_prediction HTTP/1.1" 200
2025-07-26 14:56:20 - App - INFO - 127.0.0.1:55834 - "POST /get_ner_prediction HTTP/1.1" 200
2025-07-26 15:11:12 - App - INFO - Shutting down
2025-07-26 15:11:12 - App - INFO - Waiting for application shutdown.
2025-07-26 15:11:12 - App - INFO - Application shutdown complete.
2025-07-26 15:11:12 - App - INFO - Finished server process [13316]
26-07-2025 23:45:42 - middleware_logger - INFO - Line: 28 - Starting api...
26-07-2025 23:45:42 - middleware_logger - INFO - Line: 39 - Api started
2025-07-26 23:45:42 - App - INFO - Started server process [12080]
2025-07-26 23:45:42 - App - INFO - Waiting for application startup.
2025-07-26 23:45:42 - App - INFO - Application startup complete.
2025-07-26 23:45:42 - App - INFO - Uvicorn running on http://127.0.0.1:5000 (Press CTRL+C to quit)
2025-07-26 23:49:29 - App - INFO - 127.0.0.1:56508 - "POST /get_ner_prediction HTTP/1.1" 200
2025-07-26 23:50:35 - App - INFO - 127.0.0.1:56528 - "POST /get_ner_prediction HTTP/1.1" 200
2025-07-26 23:52:16 - App - INFO - 127.0.0.1:56546 - "POST /get_ner_prediction HTTP/1.1" 200
2025-07-26 23:52:25 - App - INFO - 127.0.0.1:56551 - "POST /get_ner_prediction HTTP/1.1" 200
2025-07-26 23:54:57 - App - INFO - 127.0.0.1:56648 - "POST /get_ner_prediction HTTP/1.1" 200
2025-07-27 00:02:10 - App - INFO - 127.0.0.1:56707 - "POST /get_ner_prediction HTTP/1.1" 200
2025-07-27 00:02:48 - App - INFO - 127.0.0.1:56716 - "POST /get_ner_prediction HTTP/1.1" 200
2025-07-27 00:02:56 - App - INFO - 127.0.0.1:56722 - "POST /get_ner_prediction HTTP/1.1" 200
2025-07-27 00:03:05 - App - INFO - 127.0.0.1:56731 - "POST /get_ner_prediction HTTP/1.1" 200
2025-07-27 00:03:38 - App - INFO - 127.0.0.1:56747 - "POST /get_ner_prediction HTTP/1.1" 200
2025-07-27 00:03:52 - App - INFO - 127.0.0.1:56753 - "POST /get_ner_prediction HTTP/1.1" 200
2025-07-27 00:04:07 - App - INFO - 127.0.0.1:56758 - "POST /get_ner_prediction HTTP/1.1" 200
2025-07-27 00:04:17 - App - INFO - 127.0.0.1:56765 - "POST /get_ner_prediction HTTP/1.1" 200
2025-07-27 00:04:37 - App - INFO - 127.0.0.1:56770 - "POST /get_ner_prediction HTTP/1.1" 200
2025-07-27 00:04:53 - App - INFO - 127.0.0.1:56777 - "POST /get_ner_prediction HTTP/1.1" 200
2025-07-27 00:05:19 - App - INFO - 127.0.0.1:56785 - "POST /get_ner_prediction HTTP/1.1" 200
2025-07-27 00:05:37 - App - INFO - 127.0.0.1:56790 - "POST /get_ner_prediction HTTP/1.1" 200
2025-07-27 00:10:08 - App - INFO - 127.0.0.1:56860 - "POST /get_ner_prediction HTTP/1.1" 200
2025-07-27 00:13:04 - App - INFO - 127.0.0.1:56972 - "POST /get_ner_prediction HTTP/1.1" 200
2025-07-27 00:13:18 - App - INFO - 127.0.0.1:56982 - "POST /get_ner_prediction HTTP/1.1" 200
2025-07-27 00:14:05 - App - INFO - Shutting down
2025-07-27 00:14:05 - App - INFO - Finished server process [12080]
2025-07-27 00:14:05 - App - ERROR - Traceback (most recent call last):
  File "C:\Program Files\Python311\Lib\asyncio\runners.py", line 190, in run
    return runner.run(main)
           ^^^^^^^^^^^^^^^^
  File "C:\Program Files\Python311\Lib\asyncio\runners.py", line 118, in run
    return self._loop.run_until_complete(task)
           ^^^^^^^^^^^^^^^^^^^^^^^^^^^^^^^^^^^
  File "C:\Program Files\Python311\Lib\asyncio\base_events.py", line 640, in run_until_complete
    self.run_forever()
  File "C:\Program Files\Python311\Lib\asyncio\windows_events.py", line 321, in run_forever
    super().run_forever()
  File "C:\Program Files\Python311\Lib\asyncio\base_events.py", line 607, in run_forever
    self._run_once()
  File "C:\Program Files\Python311\Lib\asyncio\base_events.py", line 1922, in _run_once
    handle._run()
  File "C:\Program Files\Python311\Lib\asyncio\events.py", line 80, in _run
    self._context.run(self._callback, *self._args)
  File "C:\Users\table\PycharmProjects\MojeCos\venv11\Lib\site-packages\uvicorn\server.py", line 68, in serve
    with self.capture_signals():
  File "C:\Program Files\Python311\Lib\contextlib.py", line 144, in __exit__
    next(self.gen)
  File "C:\Users\table\PycharmProjects\MojeCos\venv11\Lib\site-packages\uvicorn\server.py", line 332, in capture_signals
    signal.raise_signal(captured_signal)
  File "C:\Program Files\Python311\Lib\asyncio\runners.py", line 157, in _on_sigint
    raise KeyboardInterrupt()
KeyboardInterrupt

During handling of the above exception, another exception occurred:

Traceback (most recent call last):
  File "C:\Users\table\PycharmProjects\MojeCos\venv11\Lib\site-packages\starlette\routing.py", line 700, in lifespan
    await receive()
  File "C:\Users\table\PycharmProjects\MojeCos\venv11\Lib\site-packages\uvicorn\lifespan\on.py", line 137, in receive
    return await self.receive_queue.get()
           ^^^^^^^^^^^^^^^^^^^^^^^^^^^^^^
  File "C:\Program Files\Python311\Lib\asyncio\queues.py", line 158, in get
    await getter
asyncio.exceptions.CancelledError

27-07-2025 14:04:44 - middleware_logger - INFO - Line: 28 - Starting api...
27-07-2025 14:04:45 - middleware_logger - INFO - Line: 39 - Api started
2025-07-27 14:04:45 - App - INFO - Started server process [1980]
2025-07-27 14:04:45 - App - INFO - Waiting for application startup.
2025-07-27 14:04:45 - App - INFO - Application startup complete.
2025-07-27 14:04:45 - App - INFO - Uvicorn running on http://127.0.0.1:5000 (Press CTRL+C to quit)
2025-07-27 14:08:59 - App - INFO - 127.0.0.1:52008 - "POST /get_ner_prediction HTTP/1.1" 200
2025-07-27 14:10:09 - App - INFO - 127.0.0.1:52014 - "POST /get_ner_prediction HTTP/1.1" 200
2025-07-27 14:10:19 - App - INFO - 127.0.0.1:52020 - "POST /get_ner_prediction HTTP/1.1" 200
2025-07-27 14:10:30 - App - INFO - 127.0.0.1:52025 - "POST /get_ner_prediction HTTP/1.1" 200
2025-07-27 14:13:12 - App - INFO - 127.0.0.1:52034 - "POST /get_ner_prediction HTTP/1.1" 200
2025-07-27 14:13:31 - App - INFO - 127.0.0.1:52039 - "POST /get_ner_prediction HTTP/1.1" 200
2025-07-27 14:15:27 - App - INFO - 127.0.0.1:52044 - "POST /get_ner_prediction HTTP/1.1" 200
2025-07-27 14:22:41 - App - INFO - 127.0.0.1:52057 - "POST /get_ner_prediction HTTP/1.1" 200
2025-07-27 14:22:50 - App - INFO - 127.0.0.1:52068 - "POST /get_ner_prediction HTTP/1.1" 200
2025-07-27 14:25:21 - App - INFO - 127.0.0.1:52088 - "POST /get_ner_prediction HTTP/1.1" 200
2025-07-27 14:26:39 - App - INFO - 127.0.0.1:52098 - "POST /get_ner_prediction HTTP/1.1" 200
2025-07-27 14:27:22 - App - INFO - 127.0.0.1:52120 - "POST /get_ner_prediction HTTP/1.1" 200
2025-07-27 14:33:11 - App - INFO - 127.0.0.1:52231 - "POST /get_ner_prediction HTTP/1.1" 200
2025-07-27 14:33:21 - App - INFO - 127.0.0.1:52236 - "POST /get_ner_prediction HTTP/1.1" 200
2025-07-27 14:33:34 - App - INFO - 127.0.0.1:52241 - "POST /get_ner_prediction HTTP/1.1" 200
2025-07-27 14:37:03 - App - INFO - 127.0.0.1:52249 - "POST /get_ner_prediction HTTP/1.1" 200
2025-07-27 14:39:25 - App - INFO - 127.0.0.1:52259 - "POST /get_ner_prediction HTTP/1.1" 200
2025-07-27 14:39:39 - App - INFO - 127.0.0.1:52265 - "POST /get_ner_prediction HTTP/1.1" 200
2025-07-27 14:40:14 - App - INFO - 127.0.0.1:52271 - "POST /get_ner_prediction HTTP/1.1" 200
2025-07-27 14:40:25 - App - INFO - 127.0.0.1:52276 - "POST /get_ner_prediction HTTP/1.1" 200
2025-07-27 14:41:31 - App - INFO - 127.0.0.1:52282 - "POST /get_ner_prediction HTTP/1.1" 200
2025-07-27 14:42:06 - App - INFO - 127.0.0.1:52288 - "POST /get_ner_prediction HTTP/1.1" 200
2025-07-27 14:44:28 - App - INFO - 127.0.0.1:52315 - "POST /get_ner_prediction HTTP/1.1" 200
2025-07-27 14:47:13 - App - INFO - 127.0.0.1:52338 - "POST /get_ner_prediction HTTP/1.1" 200
2025-07-27 14:48:03 - App - INFO - 127.0.0.1:52346 - "POST /get_ner_prediction HTTP/1.1" 200
2025-07-27 14:51:33 - App - INFO - 127.0.0.1:52358 - "POST /get_ner_prediction HTTP/1.1" 200
2025-07-27 14:52:28 - App - INFO - 127.0.0.1:52366 - "POST /get_ner_prediction HTTP/1.1" 200
2025-07-27 15:03:15 - App - INFO - 127.0.0.1:52418 - "POST /get_ner_prediction HTTP/1.1" 200
2025-07-27 15:07:07 - App - INFO - 127.0.0.1:52428 - "POST /get_ner_prediction HTTP/1.1" 200
2025-07-27 15:08:46 - App - INFO - 127.0.0.1:52444 - "POST /get_ner_prediction HTTP/1.1" 200
2025-07-27 15:08:49 - App - INFO - 127.0.0.1:52449 - "POST /get_ner_prediction HTTP/1.1" 200
2025-07-27 15:09:14 - App - INFO - 127.0.0.1:52455 - "POST /get_ner_prediction HTTP/1.1" 200
2025-07-27 15:09:54 - App - INFO - 127.0.0.1:52460 - "POST /get_ner_prediction HTTP/1.1" 200
2025-07-27 15:10:16 - App - INFO - 127.0.0.1:52467 - "POST /get_ner_prediction HTTP/1.1" 200
2025-07-27 15:14:41 - App - INFO - 127.0.0.1:52533 - "POST /get_ner_prediction HTTP/1.1" 200
2025-07-27 15:16:29 - App - INFO - 127.0.0.1:52543 - "POST /get_ner_prediction HTTP/1.1" 200
2025-07-27 15:17:25 - App - INFO - 127.0.0.1:52554 - "POST /get_ner_prediction HTTP/1.1" 200
2025-07-27 15:18:02 - App - INFO - 127.0.0.1:52560 - "POST /get_ner_prediction HTTP/1.1" 200
2025-07-27 15:18:10 - App - INFO - 127.0.0.1:52565 - "POST /get_ner_prediction HTTP/1.1" 200
2025-07-27 15:19:15 - App - INFO - 127.0.0.1:52597 - "POST /get_ner_prediction HTTP/1.1" 200
2025-07-27 15:19:38 - App - INFO - 127.0.0.1:52613 - "POST /get_ner_prediction HTTP/1.1" 200
2025-07-27 15:40:11 - App - INFO - 127.0.0.1:52679 - "POST /get_ner_prediction HTTP/1.1" 200
2025-07-27 15:41:40 - App - INFO - 127.0.0.1:52685 - "POST /get_ner_prediction HTTP/1.1" 200
2025-07-27 15:50:16 - App - INFO - 127.0.0.1:52711 - "POST /get_ner_prediction HTTP/1.1" 200
2025-07-27 15:50:25 - App - INFO - 127.0.0.1:52716 - "POST /get_ner_prediction HTTP/1.1" 200
2025-07-27 15:50:56 - App - INFO - 127.0.0.1:52738 - "POST /get_ner_prediction HTTP/1.1" 200
2025-07-27 15:51:00 - App - INFO - 127.0.0.1:52746 - "POST /get_ner_prediction HTTP/1.1" 200
2025-07-27 15:51:07 - App - INFO - 127.0.0.1:52753 - "POST /get_ner_prediction HTTP/1.1" 200
2025-07-27 15:51:12 - App - INFO - 127.0.0.1:52758 - "POST /get_ner_prediction HTTP/1.1" 200
2025-07-27 15:51:58 - App - INFO - 127.0.0.1:52786 - "POST /get_ner_prediction HTTP/1.1" 200
2025-07-27 16:03:07 - App - INFO - 127.0.0.1:52816 - "POST /get_ner_prediction HTTP/1.1" 200
2025-07-27 16:03:58 - App - INFO - 127.0.0.1:52821 - "POST /get_ner_prediction HTTP/1.1" 200
2025-07-27 16:04:15 - App - INFO - 127.0.0.1:52828 - "POST /get_ner_prediction HTTP/1.1" 200
2025-07-27 16:04:51 - App - INFO - 127.0.0.1:52836 - "POST /get_ner_prediction HTTP/1.1" 200
2025-07-27 16:06:41 - App - INFO - Shutting down
2025-07-27 16:06:41 - App - INFO - Waiting for application shutdown.
2025-07-27 16:06:41 - App - INFO - Application shutdown complete.
2025-07-27 16:06:41 - App - INFO - Finished server process [1980]
27-07-2025 23:08:02 - middleware_logger - INFO - Line: 28 - Starting api...
27-07-2025 23:08:03 - middleware_logger - INFO - Line: 39 - Api started
2025-07-27 23:08:03 - App - INFO - Started server process [21720]
2025-07-27 23:08:03 - App - INFO - Waiting for application startup.
2025-07-27 23:08:03 - App - INFO - Application startup complete.
2025-07-27 23:08:03 - App - INFO - Uvicorn running on http://127.0.0.1:5000 (Press CTRL+C to quit)
2025-07-27 23:41:02 - App - INFO - 127.0.0.1:53429 - "POST /get_ner_prediction HTTP/1.1" 200
2025-07-27 23:43:03 - App - INFO - 127.0.0.1:53466 - "POST /get_ner_prediction HTTP/1.1" 200
2025-07-27 23:43:11 - App - INFO - 127.0.0.1:53473 - "POST /get_ner_prediction HTTP/1.1" 200
2025-07-27 23:43:30 - App - INFO - 127.0.0.1:53480 - "POST /get_ner_prediction HTTP/1.1" 200
2025-07-27 23:57:09 - App - INFO - Shutting down
2025-07-27 23:57:09 - App - INFO - Waiting for application shutdown.
2025-07-27 23:57:09 - App - INFO - Application shutdown complete.
2025-07-27 23:57:09 - App - INFO - Finished server process [21720]
28-07-2025 21:07:26 - middleware_logger - INFO - Line: 28 - Starting api...
28-07-2025 21:07:27 - middleware_logger - INFO - Line: 39 - Api started
2025-07-28 21:07:27 - App - INFO - Started server process [11148]
2025-07-28 21:07:27 - App - INFO - Waiting for application startup.
2025-07-28 21:07:27 - App - INFO - Application startup complete.
2025-07-28 21:07:27 - App - INFO - Uvicorn running on http://127.0.0.1:5000 (Press CTRL+C to quit)
2025-07-28 22:26:10 - App - INFO - 127.0.0.1:51834 - "POST /get_ner_prediction HTTP/1.1" 200
2025-07-28 22:28:48 - App - INFO - 127.0.0.1:51866 - "POST /get_ner_prediction HTTP/1.1" 200
2025-07-28 22:30:47 - App - INFO - 127.0.0.1:51923 - "POST /get_ner_prediction HTTP/1.1" 200
2025-07-28 22:31:02 - App - INFO - 127.0.0.1:51930 - "POST /get_ner_prediction HTTP/1.1" 200
2025-07-28 22:33:20 - App - INFO - Shutting down
2025-07-28 22:33:20 - App - INFO - Waiting for application shutdown.
2025-07-28 22:33:20 - App - INFO - Application shutdown complete.
2025-07-28 22:33:20 - App - INFO - Finished server process [11148]
29-07-2025 21:20:37 - middleware_logger - INFO - Line: 28 - Starting api...
29-07-2025 21:20:38 - middleware_logger - INFO - Line: 39 - Api started
2025-07-29 21:20:38 - App - INFO - Started server process [20016]
2025-07-29 21:20:38 - App - INFO - Waiting for application startup.
2025-07-29 21:20:38 - App - INFO - Application startup complete.
2025-07-29 21:20:38 - App - INFO - Uvicorn running on http://127.0.0.1:5000 (Press CTRL+C to quit)
2025-07-29 21:20:49 - App - INFO - 127.0.0.1:56128 - "GET / HTTP/1.1" 200
2025-07-29 21:20:49 - App - INFO - 127.0.0.1:56128 - "GET /favicon.ico HTTP/1.1" 404
2025-07-29 21:28:43 - App - INFO - 127.0.0.1:56312 - "GET / HTTP/1.1" 200
2025-07-29 21:29:53 - App - INFO - Shutting down
2025-07-29 21:29:53 - App - INFO - Waiting for application shutdown.
2025-07-29 21:29:53 - App - INFO - Application shutdown complete.
2025-07-29 21:29:53 - App - INFO - Finished server process [20016]
29-07-2025 21:30:34 - middleware_logger - INFO - Line: 28 - Starting api...
29-07-2025 21:30:35 - middleware_logger - INFO - Line: 39 - Api started
2025-07-29 21:30:35 - App - INFO - Started server process [19320]
2025-07-29 21:30:35 - App - INFO - Waiting for application startup.
2025-07-29 21:30:35 - App - INFO - Application startup complete.
2025-07-29 21:30:35 - App - INFO - Uvicorn running on http://127.0.0.1:5000 (Press CTRL+C to quit)
2025-07-29 21:30:35 - App - INFO - 127.0.0.1:56350 - "GET / HTTP/1.1" 200
2025-07-29 21:30:36 - App - INFO - 127.0.0.1:56356 - "GET / HTTP/1.1" 200
2025-07-29 21:33:51 - App - INFO - 127.0.0.1:56476 - "POST /get_ner_prediction HTTP/1.1" 200
2025-07-29 21:36:53 - App - INFO - 127.0.0.1:56506 - "GET / HTTP/1.1" 200
2025-07-29 21:38:36 - App - INFO - 127.0.0.1:56523 - "GET / HTTP/1.1" 200
2025-07-29 21:39:13 - App - INFO - 127.0.0.1:56528 - "GET / HTTP/1.1" 200
2025-07-29 21:39:53 - App - INFO - 127.0.0.1:56539 - "GET / HTTP/1.1" 200
2025-07-29 21:44:43 - App - INFO - 127.0.0.1:56719 - "GET / HTTP/1.1" 200
2025-07-29 21:44:44 - App - INFO - 127.0.0.1:56721 - "GET / HTTP/1.1" 200
2025-07-29 21:47:01 - App - INFO - 127.0.0.1:56762 - "GET / HTTP/1.1" 200
2025-07-29 21:47:02 - App - INFO - 127.0.0.1:56764 - "GET / HTTP/1.1" 200
2025-07-29 21:47:10 - App - INFO - 127.0.0.1:56775 - "POST /get_ner_prediction HTTP/1.1" 200
2025-07-29 21:47:34 - App - INFO - 127.0.0.1:56787 - "POST /get_ner_prediction HTTP/1.1" 200
2025-07-29 21:48:28 - App - INFO - 127.0.0.1:56804 - "GET / HTTP/1.1" 200
2025-07-29 21:48:29 - App - INFO - 127.0.0.1:56806 - "GET / HTTP/1.1" 200
2025-07-29 21:48:33 - App - INFO - 127.0.0.1:56809 - "POST /get_ner_prediction HTTP/1.1" 200
2025-07-29 21:48:39 - App - INFO - 127.0.0.1:56817 - "POST /get_ner_prediction HTTP/1.1" 200
2025-07-29 21:49:07 - App - INFO - 127.0.0.1:56945 - "POST /get_ner_prediction HTTP/1.1" 200
2025-07-29 21:49:18 - App - INFO - 127.0.0.1:56953 - "POST /get_ner_prediction HTTP/1.1" 200
2025-07-29 21:49:19 - App - INFO - 127.0.0.1:56958 - "POST /get_ner_prediction HTTP/1.1" 200
2025-07-29 21:49:44 - App - INFO - 127.0.0.1:56970 - "GET / HTTP/1.1" 200
2025-07-29 21:49:45 - App - INFO - 127.0.0.1:56972 - "GET / HTTP/1.1" 200
2025-07-29 21:49:47 - App - INFO - 127.0.0.1:56979 - "POST /get_ner_prediction HTTP/1.1" 200
2025-07-29 21:49:49 - App - INFO - 127.0.0.1:56986 - "POST /get_ner_prediction HTTP/1.1" 200
2025-07-29 21:49:50 - App - INFO - 127.0.0.1:56993 - "POST /get_ner_prediction HTTP/1.1" 200
2025-07-29 21:49:57 - App - INFO - 127.0.0.1:57009 - "POST /get_ner_prediction HTTP/1.1" 200
2025-07-29 21:52:08 - App - INFO - 127.0.0.1:57060 - "GET / HTTP/1.1" 200
2025-07-29 21:52:09 - App - INFO - 127.0.0.1:57063 - "GET / HTTP/1.1" 200
2025-07-29 21:52:19 - App - INFO - 127.0.0.1:57076 - "POST /get_ner_prediction HTTP/1.1" 200
2025-07-29 21:52:29 - App - INFO - 127.0.0.1:57086 - "POST /get_ner_prediction HTTP/1.1" 200
2025-07-29 21:52:36 - App - INFO - 127.0.0.1:57091 - "POST /get_ner_prediction HTTP/1.1" 200
2025-07-29 21:52:57 - App - INFO - 127.0.0.1:57102 - "POST /get_ner_prediction HTTP/1.1" 200
2025-07-29 21:57:39 - App - INFO - 127.0.0.1:57188 - "GET / HTTP/1.1" 200
2025-07-29 21:57:43 - App - INFO - Shutting down
2025-07-29 21:57:43 - App - INFO - Waiting for application shutdown.
2025-07-29 21:57:43 - App - INFO - Application shutdown complete.
2025-07-29 21:57:43 - App - INFO - Finished server process [19320]
29-07-2025 21:57:52 - middleware_logger - INFO - Line: 28 - Starting api...
29-07-2025 21:57:52 - middleware_logger - INFO - Line: 39 - Api started
2025-07-29 21:57:52 - App - INFO - Started server process [2300]
2025-07-29 21:57:52 - App - INFO - Waiting for application startup.
2025-07-29 21:57:52 - App - INFO - Application startup complete.
2025-07-29 21:57:52 - App - INFO - Uvicorn running on http://127.0.0.1:5000 (Press CTRL+C to quit)
2025-07-29 21:57:58 - App - INFO - 127.0.0.1:57200 - "POST /get_ner_prediction HTTP/1.1" 200
2025-07-29 21:58:38 - App - INFO - 127.0.0.1:57209 - "GET / HTTP/1.1" 200
2025-07-29 21:58:40 - App - INFO - 127.0.0.1:57214 - "POST /get_ner_prediction HTTP/1.1" 200
